Workbook

Sheet Limitación
B2: PRIVACY | D2: Derecho de Limitación | E2: Observaciones
B3: Diciembre | C3: Pendientes de meses anteriores | D3: 0
C4: Recibidos en el mes | D4: 0
C5: Contestados - en plazo | D5: 0
C6: Contestados - fuera de plazo | D6: 0
C7: Pdte contestar en plazo | D7: 0
C8: Fuera de plazo | D8: 0
C9: Total recibidos | D9: =SUM(D3:D4) -> 0
C10: Total contestados/no contestados | D10: =SUM(D5:D8) -> 0

Sheet Hoja1

Sheet Volúmenes GDPR Manual
BJ2: Minutos al día | BK2: =8*60 -> 480
BJ3: Días al mes | BK3: 20
R4: FTE's Necesarios | AH4: MPU (min) | AV4: % distribución
B5: TOTAL | D5: Derecho de acceso | E5: Derecho de rectificación | F5: Derecho de rectificación - Cartas físicas | G5: Derecho de Borrado | H5: Derecho de oposición | I5: Derecho revisión manual - incremento límite | J5: Motivo de denegación | K5: Revisión manual | L5: ESCALADO | M5: KPI | N5: FRAUDE | O5: CALIDAD | P5: SCHUFA | R5: TOTAL FTE's | S5: Derecho de acceso | T5: Derecho de rectificación | U5: Derecho de rectificación - Cartas físicas | V5: Derecho de cancelación | W5: Derecho de oposición | X5: Derecho revisión manual - incremento límite | Y5: Motivo de denegación | Z5: Revisión manual | AA5: ESCALADO | AB5: KPI | AC5: FRAUDE | AD5: CALIDAD | AE5: SCHUFA | AG5: MPU MEDIO | AH5: Derecho de acceso | AI5: Derecho de rectificación | AJ5: Derecho de rectificación - Cartas físicas | AK5: Derecho de cancelación | AL5: Derecho de oposición | AM5: Derecho revisión manual - incremento límite | AN5: Motivo de denegación | AO5: Revisión manual | AP5: ESCALADO | AQ5: KPI | AR5: FRAUDE | AS5: CALIDAD | AT5: SCHUFA | AV5: Derecho de acceso | AW5: Derecho de rectificación | AX5: Derecho de rectificación - Cartas físicas | AY5: Derecho de cancelación | AZ5: Derecho de oposición | BA5: Derecho revisión manual - incremento límite | BB5: Razón de denegación | BC5: Revisión manual | BD5: ESCALADO | BE5: KPI | BF5: FRAUDE | BG5: CALIDAD | BH5: SCHUFA
A6: 45901 | B6: =+SUM(D6:P9) -> 2241 | C6: BNPL | D6: 12 | E6: 258 | F6: =10*20 -> 200 | G6: 40 | H6: 4 | I6: N/A | J6: 1034 | K6: 14 | L6: 22 | M6: 1 | N6: 12 | R6: =+SUM(S6:AE9) -> 13.791667 | S6: =+IFERROR((D6*AH6)/$BK$2/$BK$3,"N/A") -> 0.0775 | T6: =+IFERROR((E6*AI6)/$BK$2/$BK$3,"N/A") -> 1.800625 | U6: =+IFERROR((F6*AJ6)/$BK$2/$BK$3,"N/A") -> 0.16666667 | V6: =+IFERROR((G6*AK6)/$BK$2/$BK$3,"N/A") -> 0.175 | W6: =+IFERROR((H6*AL6)/$BK$2/$BK$3,"N/A") -> 0.018333333 | X6: =+IFERROR((I6*AM6)/$BK$2/$BK$3,"N/A") -> N/A | Y6: =+IFERROR((J6*AN6)/$BK$2/$BK$3,"N/A") -> 5.81625 | Z6: =+IFERROR((K6*AO6)/$BK$2/$BK$3,"N/A") -> 0.13708333 | ... AE6: =+IFERROR((P6*AT6)/$BK$2/$BK$3,"N/A") -> 0 | AG6: {=SUMPRODUCT(IFERROR(AH6:AO9,0),IFERROR(AV6:BC9,0)) + SUMPRODUCT(IFERROR(AP6:AT6,0),IFERROR(BD6:BH6,0))} -> 59.080768 | AH6: =+'Catálogo de servicios v0.1'!B5 -> 62 | AI6: =+'Catálogo de servicios v0.1'!C5 -> 67 | AJ6: =+'Catálogo de servicios v0.1'!D5 -> 8 | AK6: =+'Catálogo de servicios v0.1'!E5 -> 42 | AL6: =+'Catálogo de servicios v0.1'!F5 -> 44 | AM6: =+'Catálogo de servicios v0.1'!G5 -> 29 | AN6: =+'Catálogo de servicios v0.1'!H5 -> 54 | AO6: =+'Catálogo de servicios v0.1'!I5 -> 94 | AP6: =+'Catálogo de servicios v0.1'!T51 -> 225 | AQ6: =+'Catálogo de servicios v0.1'!T52 -> 480 | AR6: =+'Catálogo de servicios v0.1'!T53 -> 40 | AS6: =+'Catálogo de servicios v0.1'!T54 -> 30 | AT6: =+'Catálogo de servicios v0.1'!T55 -> 45 | AV6: =+IFERROR(D6/$B$6,"N/A") -> 0.0053547523 | AW6: =+IFERROR(E6/$B$6,"N/A") -> 0.11512718 | AX6: =+IFERROR(F6/$B$6,"N/A") -> 0.089245872 | AY6: =+IFERROR(G6/$B$6,"N/A") -> 0.017849174 | AZ6: =+IFERROR(H6/$B$6,"N/A") -> 0.0017849174 | BA6: =+IFERROR(I6/$B$6,"N/A") -> N/A | BB6: =+IFERROR(J6/$B$6,"N/A") -> 0.46140116 | BC6: =+IFERROR(K6/$B$6,"N/A") -> 0.0062472111 | ... BH6: =+IFERROR(P6/$B$6,"N/A") -> 0
C7: Amz GIL | D7: 0 | E7: 0 | F7: N/A | G7: 3 | H7: 0 | I7: N/A | J7: 26 | K7: 1 | S7: =+IFERROR((D7*AH7)/$BK$2/$BK$3,"N/A") -> 0 | T7: =+IFERROR((E7*AI7)/$BK$2/$BK$3,"N/A") -> 0 | U7: =+IFERROR((F7*AJ7)/$BK$2/$BK$3,"N/A") -> N/A | V7: =+IFERROR((G7*AK7)/$BK$2/$BK$3,"N/A") -> 0.013125 | W7: =+IFERROR((H7*AL7)/$BK$2/$BK$3,"N/A") -> 0 | X7: =+IFERROR((I7*AM7)/$BK$2/$BK$3,"N/A") -> N/A | Y7: =+IFERROR((J7*AN7)/$BK$2/$BK$3,"N/A") -> 0.14625 | Z7: =+IFERROR((K7*AO7)/$BK$2/$BK$3,"N/A") -> 0.0097916667 | AH7: =+'Catálogo de servicios v0.1'!B6 -> 90 | AI7: =+'Catálogo de servicios v0.1'!C6 -> 54 | AJ7: =+'Catálogo de servicios v0.1'!D6 -> 8 | AK7: =+'Catálogo de servicios v0.1'!E6 -> 42 | AL7: =+'Catálogo de servicios v0.1'!F6 -> 44 | AM7: =+'Catálogo de servicios v0.1'!G6 -> 29 | AN7: =+'Catálogo de servicios v0.1'!H6 -> 54 | AO7: =+'Catálogo de servicios v0.1'!I6 -> 94 | AV7: =+IFERROR(D7/$B$6,"N/A") -> 0 | AW7: =+IFERROR(E7/$B$6,"N/A") -> 0 | AX7: =+IFERROR(F7/$B$6,"N/A") -> N/A | AY7: =+IFERROR(G7/$B$6,"N/A") -> 0.0013386881 | AZ7: =+IFERROR(H7/$B$6,"N/A") -> 0 | BA7: =+IFERROR(I7/$B$6,"N/A") -> N/A | BB7: =+IFERROR(J7/$B$6,"N/A") -> 0.011601963 | BC7: =+IFERROR(K7/$B$6,"N/A") -> 0.00044622936
C8: CB | D8: 12 | E8: N/A | F8: N/A | G8: 23 | H8: 1 | I8: 10 | J8: 231 | K8: 323 | S8: =+IFERROR((D8*AH8)/$BK$2/$BK$3,"N/A") -> 0.1125 | T8: =+IFERROR((E8*AI8)/$BK$2/$BK$3,"N/A") -> N/A | U8: =+IFERROR((F8*AJ8)/$BK$2/$BK$3,"N/A") -> N/A | V8: =+IFERROR((G8*AK8)/$BK$2/$BK$3,"N/A") -> 0.11020833 | W8: =+IFERROR((H8*AL8)/$BK$2/$BK$3,"N/A") -> 0.0045833333 | X8: =+IFERROR((I8*AM8)/$BK$2/$BK$3,"N/A") -> 0.030208333 | Y8: =+IFERROR((J8*AN8)/$BK$2/$BK$3,"N/A") -> 1.299375 | Z8: =+IFERROR((K8*AO8)/$BK$2/$BK$3,"N/A") -> 3.1627083 | AH8: =+'Catálogo de servicios v0.1'!B7 -> 90 | AI8: =+'Catálogo de servicios v0.1'!C7 -> 29 | AJ8: =+'Catálogo de servicios v0.1'!D7 -> 8 | AK8: =+'Catálogo de servicios v0.1'!E7 -> 46 | AL8: =+'Catálogo de servicios v0.1'!F7 -> 44 | AM8: =+'Catálogo de servicios v0.1'!G7 -> 29 | AN8: =+'Catálogo de servicios v0.1'!H7 -> 54 | AO8: =+'Catálogo de servicios v0.1'!I7 -> 94 | AV8: =+IFERROR(D8/$B$6,"N/A") -> 0.0053547523 | AW8: =+IFERROR(E8/$B$6,"N/A") -> N/A | AX8: =+IFERROR(F8/$B$6,"N/A") -> N/A | AY8: =+IFERROR(G8/$B$6,"N/A") -> 0.010263275 | AZ8: =+IFERROR(H8/$B$6,"N/A") -> 0.00044622936 | BA8: =+IFERROR(I8/$B$6,"N/A") -> 0.0044622936 | BB8: =+IFERROR(J8/$B$6,"N/A") -> 0.10307898 | BC8: =+IFERROR(K8/$B$6,"N/A") -> 0.14413208
C9: Branch | D9: 1 | E9: N/A | F9: N/A | G9: 4 | H9: 0 | I9: N/A | J9: 5 | K9: 4 | S9: =+IFERROR((D9*AH9)/$BK$2/$BK$3,"N/A") -> 0.009375 | T9: =+IFERROR((E9*AI9)/$BK$2/$BK$3,"N/A") -> N/A | U9: =+IFERROR((F9*AJ9)/$BK$2/$BK$3,"N/A") -> N/A | V9: =+IFERROR((G9*AK9)/$BK$2/$BK$3,"N/A") -> 0.019166667 | W9: =+IFERROR((H9*AL9)/$BK$2/$BK$3,"N/A") -> 0 | X9: =+IFERROR((I9*AM9)/$BK$2/$BK$3,"N/A") -> N/A | Y9: =+IFERROR((J9*AN9)/$BK$2/$BK$3,"N/A") -> 0.028125 | Z9: =+IFERROR((K9*AO9)/$BK$2/$BK$3,"N/A") -> 0.039166667 | AH9: =+'Catálogo de servicios v0.1'!B8 -> 90 | AI9: =+'Catálogo de servicios v0.1'!C8 -> 29 | AJ9: =+'Catálogo de servicios v0.1'!D8 -> 8 | AK9: =+'Catálogo de servicios v0.1'!E8 -> 46 | AL9: =+'Catálogo de servicios v0.1'!F8 -> 44 | AM9: =+'Catálogo de servicios v0.1'!G8 -> 29 | AN9: =+'Catálogo de servicios v0.1'!H8 -> 54 | AO9: =+'Catálogo de servicios v0.1'!I8 -> 94 | AV9: =+IFERROR(D9/$B$6,"N/A") -> 0.00044622936 | AW9: =+IFERROR(E9/$B$6,"N/A") -> N/A | AX9: =+IFERROR(F9/$B$6,"N/A") -> N/A | AY9: =+IFERROR(G9/$B$6,"N/A") -> 0.0017849174 | AZ9: =+IFERROR(H9/$B$6,"N/A") -> 0 | BA9: =+IFERROR(I9/$B$6,"N/A") -> N/A | BB9: =+IFERROR(J9/$B$6,"N/A") -> 0.0022311468 | BC9: =+IFERROR(K9/$B$6,"N/A") -> 0.0017849174
A10: 45931 | B10: =+SUM(D10:P13) -> 2602 | C10: BNPL | D10: 16 | E10: 232 | F10: =10*20 -> 200 | G10: 23 | H10: 3 | I10: N/A | J10: 1096 | K10: 46 | L10: 55 | M10: 1 | N10: 12 | R10: =+SUM(S10:AE13) -> 16.651146 | S10: =+IFERROR((D10*AH10)/$BK$2/$BK$3,"N/A") -> 0.10333333 | T10: =+IFERROR((E10*AI10)/$BK$2/$BK$3,"N/A") -> 1.6191667 | U10: =+IFERROR((F10*AJ10)/$BK$2/$BK$3,"N/A") -> 0.16666667 | V10: =+IFERROR((G10*AK10)/$BK$2/$BK$3,"N/A") -> 0.100625 | W10: =+IFERROR((H10*AL10)/$BK$2/$BK$3,"N/A") -> 0.01375 | X10: =+IFERROR((I10*AM10)/$BK$2/$BK$3,"N/A") -> N/A | Y10: =+IFERROR((J10*AN10)/$BK$2/$BK$3,"N/A") -> 6.165 | Z10: =+IFERROR((K10*AO10)/$BK$2/$BK$3,"N/A") -> 0.45041667 | ... AE10: =+IFERROR((P10*AT10)/$BK$2/$BK$3,"N/A") -> 0 | AG10: {=SUMPRODUCT(IFERROR(AH10:AO13,0),IFERROR(AV10:BC13,0)) + SUMPRODUCT(IFERROR(AP10:AT10,0),IFERROR(BD10:BH10,0))} -> 61.433897 | AH10: 62 | AI10: 67 | AJ10: 8 | AK10: 42 | AL10: 44 | AM10: 29 | AN10: 54 | AO10: 94 | AP10: 225 | AQ10: 480 | AR10: 40 | AS10: 30 | AT10: 35 | AV10: =+IFERROR(D10/$B$10,"N/A") -> 0.0061491161 | AW10: =+IFERROR(E10/$B$10,"N/A") -> 0.089162183 | AX10: =+IFERROR(F10/$B$10,"N/A") -> 0.076863951 | AY10: =+IFERROR(G10/$B$10,"N/A") -> 0.0088393543 | AZ10: =+IFERROR(H10/$B$10,"N/A") -> 0.0011529593 | BA10: =+IFERROR(I10/$B$10,"N/A") -> N/A | BB10: =+IFERROR(J10/$B$10,"N/A") -> 0.42121445 | BC10: =+IFERROR(K10/$B$10,"N/A") -> 0.017678709 | ... BH10: =+IFERROR(P10/$B$10,"N/A") -> 0
C11: Amz GIL | D11: 3 | E11: 0 | F11: N/A | G11: 14 | H11: 0 | I11: N/A | J11: 116 | K11: 4 | S11: =+IFERROR((D11*AH11)/$BK$2/$BK$3,"N/A") -> 0.028125 | T11: =+IFERROR((E11*AI11)/$BK$2/$BK$3,"N/A") -> 0 | U11: =+IFERROR((F11*AJ11)/$BK$2/$BK$3,"N/A") -> N/A | V11: =+IFERROR((G11*AK11)/$BK$2/$BK$3,"N/A") -> 0.06125 | W11: =+IFERROR((H11*AL11)/$BK$2/$BK$3,"N/A") -> 0 | X11: =+IFERROR((I11*AM11)/$BK$2/$BK$3,"N/A") -> N/A | Y11: =+IFERROR((J11*AN11)/$BK$2/$BK$3,"N/A") -> 0.6525 | Z11: =+IFERROR((K11*AO11)/$BK$2/$BK$3,"N/A") -> 0.039166667 | AH11: 90 | AI11: 54 | AJ11: 8 | AK11: 42 | AL11: 44 | AM11: 29 | AN11: 54 | AO11: 94 | AV11: =+IFERROR(D11/$B$10,"N/A") -> 0.0011529593 | AW11: =+IFERROR(E11/$B$10,"N/A") -> 0 | AX11: =+IFERROR(F11/$B$10,"N/A") -> N/A | AY11: =+IFERROR(G11/$B$10,"N/A") -> 0.0053804766 | AZ11: =+IFERROR(H11/$B$10,"N/A") -> 0 | BA11: =+IFERROR(I11/$B$10,"N/A") -> N/A | BB11: =+IFERROR(J11/$B$10,"N/A") -> 0.044581091 | BC11: =+IFERROR(K11/$B$10,"N/A") -> 0.001537279
C12: CB | D12: 22 | E12: N/A | F12: N/A | G12: 46 | H12: 3 | I12: 4 | J12: 298 | K12: 344 | S12: =+IFERROR((D12*AH12)/$BK$2/$BK$3,"N/A") -> 0.20625 | T12: =+IFERROR((E12*AI12)/$BK$2/$BK$3,"N/A") -> N/A | U12: =+IFERROR((F12*AJ12)/$BK$2/$BK$3,"N/A") -> N/A | V12: =+IFERROR((G12*AK12)/$BK$2/$BK$3,"N/A") -> 0.22041667 | W12: =+IFERROR((H12*AL12)/$BK$2/$BK$3,"N/A") -> 0.01375 | X12: =+IFERROR((I12*AM12)/$BK$2/$BK$3,"N/A") -> 0.012083333 | Y12: =+IFERROR((J12*AN12)/$BK$2/$BK$3,"N/A") -> 1.67625 | Z12: =+IFERROR((K12*AO12)/$BK$2/$BK$3,"N/A") -> 3.3683333 | AH12: 90 | AI12: 29 | AJ12: 8 | AK12: 46 | AL12: 44 | AM12: 29 | AN12: 54 | AO12: 94 | AV12: =+IFERROR(D12/$B$10,"N/A") -> 0.0084550346 | AW12: =+IFERROR(E12/$B$10,"N/A") -> N/A | AX12: =+IFERROR(F12/$B$10,"N/A") -> N/A | AY12: =+IFERROR(G12/$B$10,"N/A") -> 0.017678709 | AZ12: =+IFERROR(H12/$B$10,"N/A") -> 0.0011529593 | BA12: =+IFERROR(I12/$B$10,"N/A") -> 0.001537279 | BB12: =+IFERROR(J12/$B$10,"N/A") -> 0.11452729 | BC12: =+IFERROR(K12/$B$10,"N/A") -> 0.132206
C13: Branch | D13: 0 | E13: N/A | F13: N/A | G13: 4 | H13: 0 | I13: N/A | J13: 58 | K13: 2 | S13: =+IFERROR((D13*AH13)/$BK$2/$BK$3,"N/A") -> 0 | T13: =+IFERROR((E13*AI13)/$BK$2/$BK$3,"N/A") -> N/A | U13: =+IFERROR((F13*AJ13)/$BK$2/$BK$3,"N/A") -> N/A | V13: =+IFERROR((G13*AK13)/$BK$2/$BK$3,"N/A") -> 0.019166667 | W13: =+IFERROR((H13*AL13)/$BK$2/$BK$3,"N/A") -> 0 | X13: =+IFERROR((I13*AM13)/$BK$2/$BK$3,"N/A") -> N/A | Y13: =+IFERROR((J13*AN13)/$BK$2/$BK$3,"N/A") -> 0.32625 | Z13: =+IFERROR((K13*AO13)/$BK$2/$BK$3,"N/A") -> 0.019583333 | AH13: 90 | AI13: 29 | AJ13: 8 | AK13: 46 | AL13: 44 | AM13: 29 | AN13: 54 | AO13: 94 | AV13: =+IFERROR(D13/$B$10,"N/A") -> 0 | AW13: =+IFERROR(E13/$B$10,"N/A") -> N/A | AX13: =+IFERROR(F13/$B$10,"N/A") -> N/A | AY13: =+IFERROR(G13/$B$10,"N/A") -> 0.001537279 | AZ13: =+IFERROR(H13/$B$10,"N/A") -> 0 | BA13: =+IFERROR(I13/$B$10,"N/A") -> N/A | BB13: =+IFERROR(J13/$B$10,"N/A") -> 0.022290546 | BC13: =+IFERROR(K13/$B$10,"N/A") -> 0.00076863951
A14: 45962 | B14: =+SUM(D14:P17) -> 2746 | C14: BNPL | D14: 7 | E14: 245 | F14: =10*20 -> 200 | G14: 13 | H14: 4 | I14: N/A | J14: 793 | K14: 22 | L14: 33 | M14: 1 | N14: 12 | R14: =+SUM(S14:AE17) -> 16.926458 | S14: =+IFERROR((D14*AH14)/$BK$2/$BK$3,"N/A") -> 0.045208333 | T14: =+IFERROR((E14*AI14)/$BK$2/$BK$3,"N/A") -> 1.7098958 | U14: =+IFERROR((F14*AJ14)/$BK$2/$BK$3,"N/A") -> 0.16666667 | V14: =+IFERROR((G14*AK14)/$BK$2/$BK$3,"N/A") -> 0.056875 | W14: =+IFERROR((H14*AL14)/$BK$2/$BK$3,"N/A") -> 0.018333333 | X14: =+IFERROR((I14*AM14)/$BK$2/$BK$3,"N/A") -> N/A | Y14: =+IFERROR((J14*AN14)/$BK$2/$BK$3,"N/A") -> 4.460625 | Z14: =+IFERROR((K14*AO14)/$BK$2/$BK$3,"N/A") -> 0.21541667 | ... AE14: =+IFERROR((P14*AT14)/$BK$2/$BK$3,"N/A") -> 0 | AG14: {=SUMPRODUCT(IFERROR(AH14:AO17,0),IFERROR(AV14:BC17,0)) + SUMPRODUCT(IFERROR(AP14:AT14,0),IFERROR(BD14:BH14,0))} -> 59.1748 | AH14: 62 | AI14: 67 | AJ14: 8 | AK14: 42 | AL14: 44 | AM14: 29 | AN14: 54 | AO14: 94 | AP14: 225 | AQ14: 480 | AR14: 40 | AS14: 30 | AT14: 35 | AV14: =+IFERROR(D14/$B$14,"N/A") -> 0.0025491624 | AW14: =+IFERROR(E14/$B$14,"N/A") -> 0.089220685 | AX14: =+IFERROR(F14/$B$14,"N/A") -> 0.072833212 | AY14: =+IFERROR(G14/$B$14,"N/A") -> 0.0047341588 | AZ14: =+IFERROR(H14/$B$14,"N/A") -> 0.0014566642 | BA14: =+IFERROR(I14/$B$14,"N/A") -> N/A | BB14: =+IFERROR(J14/$B$14,"N/A") -> 0.28878369 | BC14: =+IFERROR(K14/$B$14,"N/A") -> 0.0080116533 | ... BH14: =+IFERROR(P14/$B$14,"N/A") -> 0
C15: Amz GIL | D15: 3 | E15: 0 | F15: N/A | G15: 9 | H15: 1 | I15: N/A | J15: 469 | K15: 14 | S15: =+IFERROR((D15*AH15)/$BK$2/$BK$3,"N/A") -> 0.028125 | T15: =+IFERROR((E15*AI15)/$BK$2/$BK$3,"N/A") -> 0 | U15: =+IFERROR((F15*AJ15)/$BK$2/$BK$3,"N/A") -> N/A | V15: =+IFERROR((G15*AK15)/$BK$2/$BK$3,"N/A") -> 0.039375 | W15: =+IFERROR((H15*AL15)/$BK$2/$BK$3,"N/A") -> 0.0045833333 | X15: =+IFERROR((I15*AM15)/$BK$2/$BK$3,"N/A") -> N/A | Y15: =+IFERROR((J15*AN15)/$BK$2/$BK$3,"N/A") -> 2.638125 | Z15: =+IFERROR((K15*AO15)/$BK$2/$BK$3,"N/A") -> 0.13708333 | AH15: 90 | AI15: 54 | AJ15: 8 | AK15: 42 | AL15: 44 | AM15: 29 | AN15: 54 | AO15: 94 | AV15: =+IFERROR(D15/$B$14,"N/A") -> 0.0010924982 | AW15: =+IFERROR(E15/$B$14,"N/A") -> 0 | AX15: =+IFERROR(F15/$B$14,"N/A") -> N/A | AY15: =+IFERROR(G15/$B$14,"N/A") -> 0.0032774945 | AZ15: =+IFERROR(H15/$B$14,"N/A") -> 0.00036416606 | BA15: =+IFERROR(I15/$B$14,"N/A") -> N/A | BB15: =+IFERROR(J15/$B$14,"N/A") -> 0.17079388 | BC15: =+IFERROR(K15/$B$14,"N/A") -> 0.0050983248
C16: CB | D16: 7 | E16: N/A | F16: N/A | G16: 47 | H16: 6 | I16: 10 | J16: 495 | K16: 335 | S16: =+IFERROR((D16*AH16)/$BK$2/$BK$3,"N/A") -> 0.065625 | T16: =+IFERROR((E16*AI16)/$BK$2/$BK$3,"N/A") -> N/A | U16: =+IFERROR((F16*AJ16)/$BK$2/$BK$3,"N/A") -> N/A | V16: =+IFERROR((G16*AK16)/$BK$2/$BK$3,"N/A") -> 0.22520833 | W16: =+IFERROR((H16*AL16)/$BK$2/$BK$3,"N/A") -> 0.0275 | X16: =+IFERROR((I16*AM16)/$BK$2/$BK$3,"N/A") -> 0.030208333 | Y16: =+IFERROR((J16*AN16)/$BK$2/$BK$3,"N/A") -> 2.784375 | Z16: =+IFERROR((K16*AO16)/$BK$2/$BK$3,"N/A") -> 3.2802083 | AH16: 90 | AI16: 29 | AJ16: 8 | AK16: 46 | AL16: 44 | AM16: 29 | AN16: 54 | AO16: 94 | AV16: =+IFERROR(D16/$B$14,"N/A") -> 0.0025491624 | AW16: =+IFERROR(E16/$B$14,"N/A") -> N/A | AX16: =+IFERROR(F16/$B$14,"N/A") -> N/A | AY16: =+IFERROR(G16/$B$14,"N/A") -> 0.017115805 | AZ16: =+IFERROR(H16/$B$14,"N/A") -> 0.0021849964 | BA16: =+IFERROR(I16/$B$14,"N/A") -> 0.0036416606 | BB16: =+IFERROR(J16/$B$14,"N/A") -> 0.1802622 | BC16: =+IFERROR(K16/$B$14,"N/A") -> 0.12199563
C17: Branch | D17: 3 | E17: N/A | F17: N/A | G17: 0 | H17: 4 | I17: N/A | J17: 13 | K17: 0 | S17: =+IFERROR((D17*AH17)/$BK$2/$BK$3,"N/A") -> 0.028125 | T17: =+IFERROR((E17*AI17)/$BK$2/$BK$3,"N/A") -> N/A | U17: =+IFERROR((F17*AJ17)/$BK$2/$BK$3,"N/A") -> N/A | V17: =+IFERROR((G17*AK17)/$BK$2/$BK$3,"N/A") -> 0 | W17: =+IFERROR((H17*AL17)/$BK$2/$BK$3,"N/A") -> 0.018333333 | X17: =+IFERROR((I17*AM17)/$BK$2/$BK$3,"N/A") -> N/A | Y17: =+IFERROR((J17*AN17)/$BK$2/$BK$3,"N/A") -> 0.073125 | Z17: =+IFERROR((K17*AO17)/$BK$2/$BK$3,"N/A") -> 0 | AH17: 90 | AI17: 29 | AJ17: 8 | AK17: 46 | AL17: 44 | AM17: 29 | AN17: 54 | AO17: 94 | AV17: =+IFERROR(D17/$B$14,"N/A") -> 0.0010924982 | AW17: =+IFERROR(E17/$B$14,"N/A") -> N/A | AX17: =+IFERROR(F17/$B$14,"N/A") -> N/A | AY17: =+IFERROR(G17/$B$14,"N/A") -> 0 | AZ17: =+IFERROR(H17/$B$14,"N/A") -> 0.0014566642 | BA17: =+IFERROR(I17/$B$14,"N/A") -> N/A | BB17: =+IFERROR(J17/$B$14,"N/A") -> 0.0047341588 | BC17: =+IFERROR(K17/$B$14,"N/A") -> 0
A18: 45992 | B18: =+SUM(D18:P21) -> 2288 | C18: BNPL | D18: 16 | E18: 124 | F18: =10*20 -> 200 | G18: 13 | H18: 5 | I18: N/A | J18: 840 | K18: 70 | L18: 21 | M18: 1 | N18: 12 | R18: =+SUM(S18:AE21) -> 13.620521 | S18: =+IFERROR((D18*AH18)/$BK$2/$BK$3,"N/A") -> 0.10333333 | T18: =+IFERROR((E18*AI18)/$BK$2/$BK$3,"N/A") -> 0.86541667 | U18: =+IFERROR((F18*AJ18)/$BK$2/$BK$3,"N/A") -> 0.16666667 | V18: =+IFERROR((G18*AK18)/$BK$2/$BK$3,"N/A") -> 0.056875 | W18: =+IFERROR((H18*AL18)/$BK$2/$BK$3,"N/A") -> 0.022916667 | X18: =+IFERROR((I18*AM18)/$BK$2/$BK$3,"N/A") -> N/A | Y18: =+IFERROR((J18*AN18)/$BK$2/$BK$3,"N/A") -> 4.725 | Z18: =+IFERROR((K18*AO18)/$BK$2/$BK$3,"N/A") -> 0.68541667 | ... AE18: =+IFERROR((P18*AT18)/$BK$2/$BK$3,"N/A") -> 0 | AG18: {=SUMPRODUCT(IFERROR(AH18:AO21,0),IFERROR(AV18:BC21,0)) + SUMPRODUCT(IFERROR(AP18:AT18,0),IFERROR(BD18:BH18,0))} -> 57.149038 | AH18: 62 | AI18: 67 | AJ18: 8 | AK18: 42 | AL18: 44 | AM18: 29 | AN18: 54 | AO18: 94 | AP18: 225 | AQ18: 480 | AR18: 40 | AS18: 30 | AT18: 35 | AV18: =+IFERROR(D18/$B$18,"N/A") -> 0.006993007 | AW18: =+IFERROR(E18/$B$18,"N/A") -> 0.054195804 | AX18: =+IFERROR(F18/$B$18,"N/A") -> 0.087412587 | AY18: =+IFERROR(G18/$B$18,"N/A") -> 0.0056818182 | AZ18: =+IFERROR(H18/$B$18,"N/A") -> 0.0021853147 | BA18: =+IFERROR(I18/$B$18,"N/A") -> N/A | BB18: =+IFERROR(J18/$B$18,"N/A") -> 0.36713287 | BC18: =+IFERROR(K18/$B$18,"N/A") -> 0.030594406 | ... BH18: =+IFERROR(P18/$B$18,"N/A") -> 0
C19: Amz GIL | D19: 2 | E19: 2 | F19: N/A | G19: 20 | H19: 1 | I19: N/A | J19: 328 | K19: 18 | S19: =+IFERROR((D19*AH19)/$BK$2/$BK$3,"N/A") -> 0.01875 | T19: =+IFERROR((E19*AI19)/$BK$2/$BK$3,"N/A") -> 0.01125 | U19: =+IFERROR((F19*AJ19)/$BK$2/$BK$3,"N/A") -> N/A | V19: =+IFERROR((G19*AK19)/$BK$2/$BK$3,"N/A") -> 0.0875 | W19: =+IFERROR((H19*AL19)/$BK$2/$BK$3,"N/A") -> 0.0045833333 | X19: =+IFERROR((I19*AM19)/$BK$2/$BK$3,"N/A") -> N/A | Y19: =+IFERROR((J19*AN19)/$BK$2/$BK$3,"N/A") -> 1.845 | Z19: =+IFERROR((K19*AO19)/$BK$2/$BK$3,"N/A") -> 0.17625 | AH19: 90 | AI19: 54 | AJ19: 8 | AK19: 42 | AL19: 44 | AM19: 29 | AN19: 54 | AO19: 94 | AV19: =+IFERROR(D19/$B$18,"N/A") -> 0.00087412587 | AW19: =+IFERROR(E19/$B$18,"N/A") -> 0.00087412587 | AX19: =+IFERROR(F19/$B$18,"N/A") -> N/A | AY19: =+IFERROR(G19/$B$18,"N/A") -> 0.0087412587 | AZ19: =+IFERROR(H19/$B$18,"N/A") -> 0.00043706294 | BA19: =+IFERROR(I19/$B$18,"N/A") -> N/A | BB19: =+IFERROR(J19/$B$18,"N/A") -> 0.14335664 | BC19: =+IFERROR(K19/$B$18,"N/A") -> 0.0078671329
C20: CB | D20: 21 | E20: N/A | F20: N/A | G20: 65 | H20: 9 | I20: 10 | J20: 294 | K20: 194 | S20: =+IFERROR((D20*AH20)/$BK$2/$BK$3,"N/A") -> 0.196875 | T20: =+IFERROR((E20*AI20)/$BK$2/$BK$3,"N/A") -> N/A | U20: =+IFERROR((F20*AJ20)/$BK$2/$BK$3,"N/A") -> N/A | V20: =+IFERROR((G20*AK20)/$BK$2/$BK$3,"N/A") -> 0.31145833 | W20: =+IFERROR((H20*AL20)/$BK$2/$BK$3,"N/A") -> 0.04125 | X20: =+IFERROR((I20*AM20)/$BK$2/$BK$3,"N/A") -> 0.030208333 | Y20: =+IFERROR((J20*AN20)/$BK$2/$BK$3,"N/A") -> 1.65375 | Z20: =+IFERROR((K20*AO20)/$BK$2/$BK$3,"N/A") -> 1.8995833 | AH20: 90 | AI20: 29 | AJ20: 8 | AK20: 46 | AL20: 44 | AM20: 29 | AN20: 54 | AO20: 94 | AV20: =+IFERROR(D20/$B$18,"N/A") -> 0.0091783217 | AW20: =+IFERROR(E20/$B$18,"N/A") -> N/A | AX20: =+IFERROR(F20/$B$18,"N/A") -> N/A | AY20: =+IFERROR(G20/$B$18,"N/A") -> 0.028409091 | AZ20: =+IFERROR(H20/$B$18,"N/A") -> 0.0039335664 | BA20: =+IFERROR(I20/$B$18,"N/A") -> 0.0043706294 | BB20: =+IFERROR(J20/$B$18,"N/A") -> 0.1284965 | BC20: =+IFERROR(K20/$B$18,"N/A") -> 0.08479021
C21: Branch | D21: 2 | E21: N/A | F21: N/A | G21: 11 | H21: 0 | I21: N/A | J21: 8 | K21: 1 | S21: =+IFERROR((D21*AH21)/$BK$2/$BK$3,"N/A") -> 0.01875 | T21: =+IFERROR((E21*AI21)/$BK$2/$BK$3,"N/A") -> N/A | U21: =+IFERROR((F21*AJ21)/$BK$2/$BK$3,"N/A") -> N/A | V21: =+IFERROR((G21*AK21)/$BK$2/$BK$3,"N/A") -> 0.052708333 | W21: =+IFERROR((H21*AL21)/$BK$2/$BK$3,"N/A") -> 0 | X21: =+IFERROR((I21*AM21)/$BK$2/$BK$3,"N/A") -> N/A | Y21: =+IFERROR((J21*AN21)/$BK$2/$BK$3,"N/A") -> 0.045 | Z21: =+IFERROR((K21*AO21)/$BK$2/$BK$3,"N/A") -> 0.0097916667 | AH21: 90 | AI21: 29 | AJ21: 8 | AK21: 46 | AL21: 44 | AM21: 29 | AN21: 54 | AO21: 94 | AV21: =+IFERROR(D21/$B$18,"N/A") -> 0.00087412587 | AW21: =+IFERROR(E21/$B$18,"N/A") -> N/A | AX21: =+IFERROR(F21/$B$18,"N/A") -> N/A | AY21: =+IFERROR(G21/$B$18,"N/A") -> 0.0048076923 | AZ21: =+IFERROR(H21/$B$18,"N/A") -> 0 | BA21: =+IFERROR(I21/$B$18,"N/A") -> N/A | BB21: =+IFERROR(J21/$B$18,"N/A") -> 0.0034965035 | BC21: =+IFERROR(K21/$B$18,"N/A") -> 0.00043706294
A22: 46023 | B22: =+SUM(D22:P25) -> 1721 | C22: BNPL | D22: 13 | E22: 171 | F22: =10*20 -> 200 | G22: 19 | H22: 5 | I22: N/A | J22: 702 | K22: 51 | L22: 57 | M22: 1 | N22: 12 | R22: =+SUM(S22:AE25) -> 10.328542 | S22: =+IFERROR((D22*AH22)/$BK$2/$BK$3,"N/A") -> 0.083958333 | T22: =+IFERROR((E22*AI22)/$BK$2/$BK$3,"N/A") -> 1.1934375 | U22: =+IFERROR((F22*AJ22)/$BK$2/$BK$3,"N/A") -> 0.16666667 | V22: =+IFERROR((G22*AK22)/$BK$2/$BK$3,"N/A") -> 0.083125 | W22: =+IFERROR((H22*AL22)/$BK$2/$BK$3,"N/A") -> 0.022916667 | X22: =+IFERROR((I22*AM22)/$BK$2/$BK$3,"N/A") -> N/A | Y22: =+IFERROR((J22*AN22)/$BK$2/$BK$3,"N/A") -> 3.94875 | Z22: =+IFERROR((K22*AO22)/$BK$2/$BK$3,"N/A") -> 0.499375 | ... AE22: =+IFERROR((P22*AT22)/$BK$2/$BK$3,"N/A") -> 0 | AG22: {=SUMPRODUCT(IFERROR(AH22:AO25,0),IFERROR(AV22:BC25,0)) + SUMPRODUCT(IFERROR(AP22:AT22,0),IFERROR(BD22:BH22,0))} -> 57.614178 | AH22: 62 | AI22: 67 | AJ22: 8 | AK22: 42 | AL22: 44 | AM22: 29 | AN22: 54 | AO22: 94 | AP22: 225 | AQ22: 480 | AR22: 40 | AS22: 30 | AT22: 35 | AV22: =+IFERROR(D22/$B$22,"N/A") -> 0.0075537478 | AW22: =+IFERROR(E22/$B$22,"N/A") -> 0.099360837 | AX22: =+IFERROR(F22/$B$22,"N/A") -> 0.1162115 | AY22: =+IFERROR(G22/$B$22,"N/A") -> 0.011040093 | AZ22: =+IFERROR(H22/$B$22,"N/A") -> 0.0029052876 | BA22: =+IFERROR(I22/$B$22,"N/A") -> N/A | BB22: =+IFERROR(J22/$B$22,"N/A") -> 0.40790238 | BC22: =+IFERROR(K22/$B$22,"N/A") -> 0.029633934 | ... BH22: =+IFERROR(P22/$B$22,"N/A") -> 0
C23: Amz GIL | D23: 2 | E23: 1 | F23: N/A | G23: 30 | H23: 0 | I23: N/A | J23: 142 | K23: 8 | S23: =+IFERROR((D23*AH23)/$BK$2/$BK$3,"N/A") -> 0.01875 | T23: =+IFERROR((E23*AI23)/$BK$2/$BK$3,"N/A") -> 0.005625 | U23: =+IFERROR((F23*AJ23)/$BK$2/$BK$3,"N/A") -> N/A | V23: =+IFERROR((G23*AK23)/$BK$2/$BK$3,"N/A") -> 0.13125 | W23: =+IFERROR((H23*AL23)/$BK$2/$BK$3,"N/A") -> 0 | X23: =+IFERROR((I23*AM23)/$BK$2/$BK$3,"N/A") -> N/A | Y23: =+IFERROR((J23*AN23)/$BK$2/$BK$3,"N/A") -> 0.79875 | Z23: =+IFERROR((K23*AO23)/$BK$2/$BK$3,"N/A") -> 0.078333333 | AG23: {=SUMPRODUCT(IFERROR(AH9:AO12,0),IFERROR(AV9:BC12,0)) + SUMPRODUCT(IFERROR(AP9:AT9,0),IFERROR(BD9:BH9,0))} -> 55.372868 | AH23: 90 | AI23: 54 | AJ23: 8 | AK23: 42 | AL23: 44 | AM23: 29 | AN23: 54 | AO23: 94 | AV23: =+IFERROR(D23/$B$22,"N/A") -> 0.001162115 | AW23: =+IFERROR(E23/$B$22,"N/A") -> 0.00058105752 | AX23: =+IFERROR(F23/$B$22,"N/A") -> N/A | AY23: =+IFERROR(G23/$B$22,"N/A") -> 0.017431726 | AZ23: =+IFERROR(H23/$B$22,"N/A") -> 0 | BA23: =+IFERROR(I23/$B$22,"N/A") -> N/A | BB23: =+IFERROR(J23/$B$22,"N/A") -> 0.082510169 | BC23: =+IFERROR(K23/$B$22,"N/A") -> 0.0046484602
C24: CB | D24: 14 | E24: N/A | F24: N/A | G24: 25 | H24: 9 | I24: 14 | J24: 169 | K24: 37 | S24: =+IFERROR((D24*AH24)/$BK$2/$BK$3,"N/A") -> 0.13125 | T24: =+IFERROR((E24*AI24)/$BK$2/$BK$3,"N/A") -> N/A | U24: =+IFERROR((F24*AJ24)/$BK$2/$BK$3,"N/A") -> N/A | V24: =+IFERROR((G24*AK24)/$BK$2/$BK$3,"N/A") -> 0.11979167 | W24: =+IFERROR((H24*AL24)/$BK$2/$BK$3,"N/A") -> 0.04125 | X24: =+IFERROR((I24*AM24)/$BK$2/$BK$3,"N/A") -> 0.042291667 | Y24: =+IFERROR((J24*AN24)/$BK$2/$BK$3,"N/A") -> 0.950625 | Z24: =+IFERROR((K24*AO24)/$BK$2/$BK$3,"N/A") -> 0.36229167 | AG24: {=SUMPRODUCT(IFERROR(AH10:AO13,0),IFERROR(AV10:BC13,0)) + SUMPRODUCT(IFERROR(AP10:AT10,0),IFERROR(BD10:BH10,0))} -> 61.433897 | AH24: 90 | AI24: 29 | AJ24: 8 | AK24: 46 | AL24: 44 | AM24: 29 | AN24: 54 | AO24: 94 | AV24: =+IFERROR(D24/$B$22,"N/A") -> 0.0081348053 | AW24: =+IFERROR(E24/$B$22,"N/A") -> N/A | AX24: =+IFERROR(F24/$B$22,"N/A") -> N/A | AY24: =+IFERROR(G24/$B$22,"N/A") -> 0.014526438 | AZ24: =+IFERROR(H24/$B$22,"N/A") -> 0.0052295177 | BA24: =+IFERROR(I24/$B$22,"N/A") -> 0.0081348053 | BB24: =+IFERROR(J24/$B$22,"N/A") -> 0.098198722 | BC24: =+IFERROR(K24/$B$22,"N/A") -> 0.021499128
C25: Branch | D25: 0 | E25: N/A | F25: N/A | G25: 10 | H25: 1 | I25: N/A | J25: 27 | K25: 1 | S25: =+IFERROR((D25*AH25)/$BK$2/$BK$3,"N/A") -> 0 | T25: =+IFERROR((E25*AI25)/$BK$2/$BK$3,"N/A") -> N/A | U25: =+IFERROR((F25*AJ25)/$BK$2/$BK$3,"N/A") -> N/A | V25: =+IFERROR((G25*AK25)/$BK$2/$BK$3,"N/A") -> 0.047916667 | W25: =+IFERROR((H25*AL25)/$BK$2/$BK$3,"N/A") -> 0.0045833333 | X25: =+IFERROR((I25*AM25)/$BK$2/$BK$3,"N/A") -> N/A | Y25: =+IFERROR((J25*AN25)/$BK$2/$BK$3,"N/A") -> 0.151875 | Z25: =+IFERROR((K25*AO25)/$BK$2/$BK$3,"N/A") -> 0.0097916667 | AG25: {=SUMPRODUCT(IFERROR(AH11:AO14,0),IFERROR(AV11:BC14,0)) + SUMPRODUCT(IFERROR(AP11:AT11,0),IFERROR(BD11:BH11,0))} -> 47.83845 | AH25: 90 | AI25: 29 | AJ25: 8 | AK25: 46 | AL25: 44 | AM25: 29 | AN25: 54 | AO25: 94 | AV25: =+IFERROR(D25/$B$22,"N/A") -> 0 | AW25: =+IFERROR(E25/$B$22,"N/A") -> N/A | AX25: =+IFERROR(F25/$B$22,"N/A") -> N/A | AY25: =+IFERROR(G25/$B$22,"N/A") -> 0.0058105752 | AZ25: =+IFERROR(H25/$B$22,"N/A") -> 0.00058105752 | BA25: =+IFERROR(I25/$B$22,"N/A") -> N/A | BB25: =+IFERROR(J25/$B$22,"N/A") -> 0.015688553 | BC25: =+IFERROR(K25/$B$22,"N/A") -> 0.00058105752
A26: 46054 | B26: =+SUM(D26:P29) -> 1466 | C26: BNPL | D26: ='[1]TD_NO TOUCH'!$U$9 -> 13 | E26: ='[1]TD_NO TOUCH'!$V$9 -> 162 | F26: 200 | G26: ='[1]TD_NO TOUCH'!$X$9 -> 49 | H26: ='[1]TD_NO TOUCH'!$Y$9 -> 7 | I26: N/A | J26: ='[1]TD_NO TOUCH'!$AA$9 -> 429 | K26: ='[1]TD_NO TOUCH'!$AB$9 -> 27 | L26: 32 | M26: 1 | N26: 20 | R26: =+SUM(S26:AE29) -> 8.2230208 | S26: =+IFERROR((D26*AH26)/$BK$2/$BK$3,"N/A") -> 0.083958333 | T26: =+IFERROR((E26*AI26)/$BK$2/$BK$3,"N/A") -> 1.130625 | U26: =+IFERROR((F26*AJ26)/$BK$2/$BK$3,"N/A") -> 0.16666667 | V26: =+IFERROR((G26*AK26)/$BK$2/$BK$3,"N/A") -> 0.214375 | W26: =+IFERROR((H26*AL26)/$BK$2/$BK$3,"N/A") -> 0.032083333 | X26: =+IFERROR((I26*AM26)/$BK$2/$BK$3,"N/A") -> N/A | Y26: =+IFERROR((J26*AN26)/$BK$2/$BK$3,"N/A") -> 2.413125 | Z26: =+IFERROR((K26*AO26)/$BK$2/$BK$3,"N/A") -> 0.264375 | ... AE26: =+IFERROR((P26*AT26)/$BK$2/$BK$3,"N/A") -> 0 | AH26: 62 | AI26: 67 | AJ26: 8 | AK26: 42 | AL26: 44 | AM26: 29 | AN26: 54 | AO26: 94 | AP26: 225 | AQ26: 480 | AR26: 40 | AS26: 30 | AT26: 35
C27: Amz GIL | D27: ='[2]TD_NO TOCAR'!$V$29 -> 4 | E27: ='[2]TD_NO TOCAR'!$W$29 -> 5 | F27: N/A | G27: ='[2]TD_NO TOCAR'!$Y$29 -> 24 | H27: ='[2]TD_NO TOCAR'!$Z$29 -> 4 | I27: N/A | J27: ='[2]TD_NO TOCAR'!$AB$29 -> 250 | K27: ='[2]TD_NO TOCAR'!$AC$29 -> 19 | S27: =+IFERROR((D27*AH27)/$BK$2/$BK$3,"N/A") -> 0.0375 | T27: =+IFERROR((E27*AI27)/$BK$2/$BK$3,"N/A") -> 0.028125 | U27: =+IFERROR((F27*AJ27)/$BK$2/$BK$3,"N/A") -> N/A | V27: =+IFERROR((G27*AK27)/$BK$2/$BK$3,"N/A") -> 0.105 | W27: =+IFERROR((H27*AL27)/$BK$2/$BK$3,"N/A") -> 0.018333333 | X27: =+IFERROR((I27*AM27)/$BK$2/$BK$3,"N/A") -> N/A | Y27: =+IFERROR((J27*AN27)/$BK$2/$BK$3,"N/A") -> 1.40625 | Z27: =+IFERROR((K27*AO27)/$BK$2/$BK$3,"N/A") -> 0.18604167 | AH27: 90 | AI27: 54 | AJ27: 8 | AK27: 42 | AL27: 44 | AM27: 29 | AN27: 54 | AO27: 94
C28: CB | D28: ='[3]TD_NO TOUCH'!$V$32 -> 5 | E28: ='[3]TD_NO TOUCH'!$W$32 -> N/A | F28: ='[3]TD_NO TOUCH'!$X$32 -> N/A | G28: ='[3]TD_NO TOUCH'!$Y$32 -> 27 | H28: ='[3]TD_NO TOUCH'!$Z$32 -> 2 | I28: ='[3]TD_NO TOUCH'!$AA$32 -> 7 | J28: ='[3]TD_NO TOUCH'!$AB$32 -> 117 | K28: ='[3]TD_NO TOUCH'!$AC$32 -> 11 | S28: =+IFERROR((D28*AH28)/$BK$2/$BK$3,"N/A") -> 0.046875 | T28: =+IFERROR((E28*AI28)/$BK$2/$BK$3,"N/A") -> N/A | U28: =+IFERROR((F28*AJ28)/$BK$2/$BK$3,"N/A") -> N/A | V28: =+IFERROR((G28*AK28)/$BK$2/$BK$3,"N/A") -> 0.129375 | W28: =+IFERROR((H28*AL28)/$BK$2/$BK$3,"N/A") -> 0.0091666667 | X28: =+IFERROR((I28*AM28)/$BK$2/$BK$3,"N/A") -> 0.021145833 | Y28: =+IFERROR((J28*AN28)/$BK$2/$BK$3,"N/A") -> 0.658125 | Z28: =+IFERROR((K28*AO28)/$BK$2/$BK$3,"N/A") -> 0.10770833 | AH28: 90 | AI28: 29 | AJ28: 8 | AK28: 46 | AL28: 44 | AM28: 29 | AN28: 54 | AO28: 94
C29: Branch | D29: 0 | E29: N/A | F29: N/A | G29: 6 | H29: 1 | I29: N/A | J29: 44 | K29: 0 | S29: =+IFERROR((D29*AH29)/$BK$2/$BK$3,"N/A") -> 0 | T29: =+IFERROR((E29*AI29)/$BK$2/$BK$3,"N/A") -> N/A | U29: =+IFERROR((F29*AJ29)/$BK$2/$BK$3,"N/A") -> N/A | V29: =+IFERROR((G29*AK29)/$BK$2/$BK$3,"N/A") -> 0.02875 | W29: =+IFERROR((H29*AL29)/$BK$2/$BK$3,"N/A") -> 0.0045833333 | X29: =+IFERROR((I29*AM29)/$BK$2/$BK$3,"N/A") -> N/A | Y29: =+IFERROR((J29*AN29)/$BK$2/$BK$3,"N/A") -> 0.2475 | Z29: =+IFERROR((K29*AO29)/$BK$2/$BK$3,"N/A") -> 0 | AH29: 90 | AI29: 29 | AJ29: 8 | AK29: 46 | AL29: 44 | AM29: 29 | AN29: 54 | AO29: 94
A30: 46082 | C30: BNPL | D30: ='[4]TD_NO TOUCH'!U10 -> 1 | E30: ='[4]TD_NO TOUCH'!V10 -> 12 | F30: ='[4]TD_NO TOUCH'!W10 -> 200 | G30: ='[4]TD_NO TOUCH'!X10 -> 0 | H30: ='[4]TD_NO TOUCH'!Y10 -> 0 | I30: ='[4]TD_NO TOUCH'!Z10 -> N/A | J30: ='[4]TD_NO TOUCH'!AA10 -> 10 | K30: ='[4]TD_NO TOUCH'!AB10 -> 1 | R30: =+SUM(S30:Z33) -> 0
C31: Amz GIL | D31: ='[2]TD_NO TOCAR'!V30 -> 0 | E31: ='[2]TD_NO TOCAR'!W30 -> 0 | F31: ='[2]TD_NO TOCAR'!X30 -> N/A | G31: ='[2]TD_NO TOCAR'!Y30 -> 0 | H31: ='[2]TD_NO TOCAR'!Z30 -> 0 | I31: ='[2]TD_NO TOCAR'!AA30 -> N/A | J31: ='[2]TD_NO TOCAR'!AB30 -> 24 | K31: ='[2]TD_NO TOCAR'!AC30 -> 0
C32: CB
C33: Branch
A34: 46113 | C34: BNPL | R34: =+SUM(S34:Z37) -> 0
C35: Amz GIL
C36: CB
C37: Branch
AH39: =+IFERROR((AH22*AV22),0) -> 0.46833236 | AI39: =+IFERROR((AI22*AW22),0) -> 6.6571761 | AJ39: =+IFERROR((AJ22*AX22),0) -> 0.92969204 | AK39: =+IFERROR((AK22*AY22),0) -> 0.4636839 | AL39: =+IFERROR((AL22*AZ22),0) -> 0.12783266 | AM39: =+IFERROR((AM22*BA22),0) -> 0 | AN39: =+IFERROR((AN22*BB22),0) -> 22.026729 | AO39: =+IFERROR((AO22*BC22),0) -> 2.7855898 | ... AT39: =+IFERROR((AT22*BH22),0) -> 0
AH40: =+IFERROR((AH23*AV23),0) -> 0.10459035 | AI40: =+IFERROR((AI23*AW23),0) -> 0.031377106 | AJ40: =+IFERROR((AJ23*AX23),0) -> 0 | AK40: =+IFERROR((AK23*AY23),0) -> 0.73213248 | AL40: =+IFERROR((AL23*AZ23),0) -> 0 | AM40: =+IFERROR((AM23*BA23),0) -> 0 | AN40: =+IFERROR((AN23*BB23),0) -> 4.4555491 | AO40: =+IFERROR((AO23*BC23),0) -> 0.43695526
L41: =+AVERAGE(SUM(L6:N9),SUM(L10:N13),SUM(L14:N17),SUM(L18:N21),SUM(L22:N25)) -> 50.6 | AH41: =+IFERROR((AH24*AV24),0) -> 0.73213248 | AI41: =+IFERROR((AI24*AW24),0) -> 0 | AJ41: =+IFERROR((AJ24*AX24),0) -> 0 | AK41: =+IFERROR((AK24*AY24),0) -> 0.66821615 | AL41: =+IFERROR((AL24*AZ24),0) -> 0.23009878 | AM41: =+IFERROR((AM24*BA24),0) -> 0.23590936 | AN41: =+IFERROR((AN24*BB24),0) -> 5.302731 | AO41: =+IFERROR((AO24*BC24),0) -> 2.0209181
AH42: =+IFERROR((AH25*AV25),0) -> 0 | AI42: =+IFERROR((AI25*AW25),0) -> 0 | AJ42: =+IFERROR((AJ25*AX25),0) -> 0 | AK42: =+IFERROR((AK25*AY25),0) -> 0.26728646 | AL42: =+IFERROR((AL25*AZ25),0) -> 0.025566531 | AM42: =+IFERROR((AM25*BA25),0) -> 0 | AN42: =+IFERROR((AN25*BB25),0) -> 0.84718187 | AO42: =+IFERROR((AO25*BC25),0) -> 0.054619407
...

Sheet Catálogo de servicios v0.1
B3: RESUMEN DE MPU'S POR DERECHO GDPR (minutos) | J3: TAREAS ADICIONALES GDPR (min)
B4: Derecho de acceso | C4: Derecho de rectificación | D4: Derecho de rectificación - Cartas físicas | E4: Derecho de borrado | F4: Derecho de oposición | G4: Derecho revisión manual - incremento límite | H4: Razón de denegación | I4: Revisión manual | J4: ESCALADO | K4: KPI | L4: FRAUDE | M4: CALIDAD | N4: SCHUFA
A5: BNPL | B5: =+T19 -> 62 | C5: =+T23 -> 67 | D5: =+T27 -> 8 | E5: =+T31 -> 42 | F5: =+T35 -> 44 | G5: =+T39 -> 29 | H5: =+T43 -> 54 | I5: =+T47 -> 94 | J5: =+$T51 -> 225 | K5: =+$T52 -> 480 | L5: =+$T53 -> 40 | M5: =+$T54 -> 30 | N5: =+$T55 -> 45
A6: Amz GIL | B6: =+T20 -> 90 | C6: =+T24 -> 54 | D6: =+T28 -> 8 | E6: =+T32 -> 42 | F6: =+T36 -> 44 | G6: =+T40 -> 29 | H6: =+T44 -> 54 | I6: =+T48 -> 94
A7: CB | B7: =+T21 -> 90 | C7: =+T25 -> 29 | D7: =+T29 -> 8 | E7: =+T33 -> 46 | F7: =+T37 -> 44 | G7: =+T41 -> 29 | H7: =+T45 -> 54 | I7: =+T49 -> 94
A8: Branch | B8: =+T22 -> 90 | C8: =+T26 -> 29 | D8: =+T30 -> 8 | E8: =+T34 -> 46 | F8: =+T38 -> 44 | G8: =+T42 -> 29 | H8: =+T46 -> 54 | I8: =+T50 -> 94
G13: =+SUM(IF(D32=1,(1*$C$60),0)+IF(E32=1,(1*$C$63),0)+IF(F32=1,(1*$C$68),0)) -> 29
O17: ESCALADO | P17: KPI | Q17: FRAUDE | R17: CALIDAD | S17: SCHUFA
A18: Nombre derecho | B18: Producto | C18: Servicio | D18: Tarea 1 | E18: Tarea 2 | F18: Tarea 3 | G18: Tarea 4 | H18: Tarea 5 | I18: Tarea 6 | J18: Tarea 7 | K18: Tarea 8 | L18: Tarea 9 | M18: Tarea 10 | N18: Tarea 11 | O18: Tarea 12 | P18: Tarea 13 | Q18: Tarea 14 | R18: Tarea 15 | S18: Tarea 16 | T18: MPU
A19: Derecho de acceso | B19: BNPL | C19: =+_xlfn.CONCAT(A19," - ",B19) -> Derecho de acceso - BNPL | D19: 1 | E19: 1 | F19: 1 | G19: 0 | H19: 0 | I19: 0 | J19: 0 | K19: 0 | L19: 0 | M19: 0 | N19: 0 | O19: N/A | P19: N/A | Q19: N/A | R19: N/A | S19: N/A | T19: =+SUM(IF(D19=1,(1*$C$60),0)+IF(E19=1,(1*$C$63),0)+IF(F19=1,(1*$C$68),0)+IF(G19=1,(1*$C$75),0)+IF(H19=1,(1*$C$81),0)+IF(I19=1,(1*$C$86),0)+IF(J19=1,(1*$C$91),0)+IF(K19=1,(1*$C$96),0)+IF(L19=1,(1*$C$101),0)+IF(M19=1,(1*$C$106),0)+IF(N19=1,(1*$C$111),0)+IF(O19=1,(1*$C$115),0)+IF(P19=1,(1*$C$121),0)+IF(Q19=1,(1*$C$124),0)+IF(R19=1,(1*$C$129),0)+IF(S19=1,(1*$C$133),0)) -> 62
A20: Derecho de acceso | B20: Amz GIL | C20: =+_xlfn.CONCAT(A20," - ",B20) -> Derecho de acceso - Amz GIL | D20: 1 | E20: 1 | F20: 0 | G20: 1 | H20: 0 | I20: 0 | J20: 0 | K20: 0 | L20: 0 | M20: 0 | N20: 0 | O20: N/A | P20: N/A | Q20: N/A | R20: N/A | S20: N/A | T20: =+SUM(IF(D20=1,(1*$C$60),0)+IF(E20=1,(1*$C$63),0)+IF(F20=1,(1*$C$68),0)+IF(G20=1,(1*$C$75),0)+IF(H20=1,(1*$C$81),0)+IF(I20=1,(1*$C$86),0)+IF(J20=1,(1*$C$91),0)+IF(K20=1,(1*$C$96),0)+IF(L20=1,(1*$C$101),0)+IF(M20=1,(1*$C$106),0)+IF(N20=1,(1*$C$111),0)+IF(O20=1,(1*$C$115),0)+IF(P20=1,(1*$C$121),0)+IF(Q20=1,(1*$C$124),0)+IF(R20=1,(1*$C$129),0)+IF(S20=1,(1*$C$133),0)) -> 90
A21: Derecho de acceso | B21: CB | C21: =+_xlfn.CONCAT(A21," - ",B21) -> Derecho de acceso - CB | D21: 1 | E21: 1 | F21: 0 | G21: 1 | H21: 0 | I21: 0 | J21: 0 | K21: 0 | L21: 0 | M21: 0 | N21: 0 | O21: N/A | P21: N/A | Q21: N/A | R21: N/A | S21: N/A | T21: =+SUM(IF(D21=1,(1*$C$60),0)+IF(E21=1,(1*$C$63),0)+IF(F21=1,(1*$C$68),0)+IF(G21=1,(1*$C$75),0)+IF(H21=1,(1*$C$81),0)+IF(I21=1,(1*$C$86),0)+IF(J21=1,(1*$C$91),0)+IF(K21=1,(1*$C$96),0)+IF(L21=1,(1*$C$101),0)+IF(M21=1,(1*$C$106),0)+IF(N21=1,(1*$C$111),0)+IF(O21=1,(1*$C$115),0)+IF(P21=1,(1*$C$121),0)+IF(Q21=1,(1*$C$124),0)+IF(R21=1,(1*$C$129),0)+IF(S21=1,(1*$C$133),0)) -> 90
A22: Derecho de acceso | B22: Branch | C22: =+_xlfn.CONCAT(A22," - ",B22) -> Derecho de acceso - Branch | D22: 1 | E22: 1 | F22: 0 | G22: 1 | H22: 0 | I22: 0 | J22: 0 | K22: 0 | L22: 0 | M22: 0 | N22: 0 | O22: N/A | P22: N/A | Q22: N/A | R22: N/A | S22: N/A | T22: =+SUM(IF(D22=1,(1*$C$60),0)+IF(E22=1,(1*$C$63),0)+IF(F22=1,(1*$C$68),0)+IF(G22=1,(1*$C$75),0)+IF(H22=1,(1*$C$81),0)+IF(I22=1,(1*$C$86),0)+IF(J22=1,(1*$C$91),0)+IF(K22=1,(1*$C$96),0)+IF(L22=1,(1*$C$101),0)+IF(M22=1,(1*$C$106),0)+IF(N22=1,(1*$C$111),0)+IF(O22=1,(1*$C$115),0)+IF(P22=1,(1*$C$121),0)+IF(Q22=1,(1*$C$124),0)+IF(R22=1,(1*$C$129),0)+IF(S22=1,(1*$C$133),0)) -> 90
A23: Derecho de rectificación | B23: BNPL | C23: =+_xlfn.CONCAT(A23," - ",B23) -> Derecho de rectificación - BNPL | D23: 1 | E23: 1 | F23: 0 | G23: 0 | H23: 1 | I23: 1 | J23: 0 | K23: 0 | L23: 0 | M23: 0 | N23: 0 | O23: N/A | P23: N/A | Q23: N/A | R23: N/A | S23: N/A | T23: =+SUM(IF(D23=1,(1*$C$60),0)+IF(E23=1,(1*$C$63),0)+IF(F23=1,(1*$C$68),0)+IF(G23=1,(1*$C$75),0)+IF(H23=1,(1*$C$81),0)+IF(I23=1,(1*$C$86),0)+IF(J23=1,(1*$C$91),0)+IF(K23=1,(1*$C$96),0)+IF(L23=1,(1*$C$101),0)+IF(M23=1,(1*$C$106),0)+IF(N23=1,(1*$C$111),0)+IF(O23=1,(1*$C$115),0)+IF(P23=1,(1*$C$121),0)+IF(Q23=1,(1*$C$124),0)+IF(R23=1,(1*$C$129),0)+IF(S23=1,(1*$C$133),0)) -> 67
A24: Derecho de rectificación | B24: Amz GIL | C24: =+_xlfn.CONCAT(A24," - ",B24) -> Derecho de rectificación - Amz GIL | D24: 1 | E24: 1 | F24: 0 | G24: 0 | H24: 1 | I24: 0 | J24: 0 | K24: 0 | L24: 0 | M24: 0 | N24: 0 | O24: N/A | P24: N/A | Q24: N/A | R24: N/A | S24: N/A | T24: =+SUM(IF(D24=1,(1*$C$60),0)+IF(E24=1,(1*$C$63),0)+IF(F24=1,(1*$C$68),0)+IF(G24=1,(1*$C$75),0)+IF(H24=1,(1*$C$81),0)+IF(I24=1,(1*$C$86),0)+IF(J24=1,(1*$C$91),0)+IF(K24=1,(1*$C$96),0)+IF(L24=1,(1*$C$101),0)+IF(M24=1,(1*$C$106),0)+IF(N24=1,(1*$C$111),0)+IF(O24=1,(1*$C$115),0)+IF(P24=1,(1*$C$121),0)+IF(Q24=1,(1*$C$124),0)+IF(R24=1,(1*$C$129),0)+IF(S24=1,(1*$C$133),0)) -> 54
A25: Derecho de rectificación | B25: CB | C25: =+_xlfn.CONCAT(A25," - ",B25) -> Derecho de rectificación - CB | D25: 1 | E25: 1 | F25: 0 | G25: 0 | H25: 0 | I25: 0 | J25: 0 | K25: 0 | L25: 0 | M25: 0 | N25: 0 | O25: N/A | P25: N/A | Q25: N/A | R25: N/A | S25: N/A | T25: =+SUM(IF(D25=1,(1*$C$60),0)+IF(E25=1,(1*$C$63),0)+IF(F25=1,(1*$C$68),0)+IF(G25=1,(1*$C$75),0)+IF(H25=1,(1*$C$81),0)+IF(I25=1,(1*$C$86),0)+IF(J25=1,(1*$C$91),0)+IF(K25=1,(1*$C$96),0)+IF(L25=1,(1*$C$101),0)+IF(M25=1,(1*$C$106),0)+IF(N25=1,(1*$C$111),0)+IF(O25=1,(1*$C$115),0)+IF(P25=1,(1*$C$121),0)+IF(Q25=1,(1*$C$124),0)+IF(R25=1,(1*$C$129),0)+IF(S25=1,(1*$C$133),0)) -> 29
A26: Derecho de rectificación | B26: Branch | C26: =+_xlfn.CONCAT(A26," - ",B26) -> Derecho de rectificación - Branch | D26: 1 | E26: 1 | F26: 0 | G26: 0 | H26: 0 | I26: 0 | J26: 0 | K26: 0 | L26: 0 | M26: 0 | N26: 0 | O26: N/A | P26: N/A | Q26: N/A | R26: N/A | S26: N/A | T26: =+SUM(IF(D26=1,(1*$C$60),0)+IF(E26=1,(1*$C$63),0)+IF(F26=1,(1*$C$68),0)+IF(G26=1,(1*$C$75),0)+IF(H26=1,(1*$C$81),0)+IF(I26=1,(1*$C$86),0)+IF(J26=1,(1*$C$91),0)+IF(K26=1,(1*$C$96),0)+IF(L26=1,(1*$C$101),0)+IF(M26=1,(1*$C$106),0)+IF(N26=1,(1*$C$111),0)+IF(O26=1,(1*$C$115),0)+IF(P26=1,(1*$C$121),0)+IF(Q26=1,(1*$C$124),0)+IF(R26=1,(1*$C$129),0)+IF(S26=1,(1*$C$133),0)) -> 29
A27: Derecho de rectificación - Cartas físicas | B27: BNPL | C27: =+_xlfn.CONCAT(A27," - ",B27) -> Derecho de rectificación - Cartas físicas - BNPL | D27: 1 | E27: 0 | F27: 0 | G27: 0 | H27: 0 | I27: 0 | J27: 0 | K27: 0 | L27: 0 | M27: 0 | N27: 0 | O27: N/A | P27: N/A | Q27: N/A | R27: N/A | S27: N/A | T27: =+SUM(IF(D27=1,(1*$C$60),0)+IF(E27=1,(1*$C$63),0)+IF(F27=1,(1*$C$68),0)+IF(G27=1,(1*$C$75),0)+IF(H27=1,(1*$C$81),0)+IF(I27=1,(1*$C$86),0)+IF(J27=1,(1*$C$91),0)+IF(K27=1,(1*$C$96),0)+IF(L27=1,(1*$C$101),0)+IF(M27=1,(1*$C$106),0)+IF(N27=1,(1*$C$111),0)+IF(O27=1,(1*$C$115),0)+IF(P27=1,(1*$C$121),0)+IF(Q27=1,(1*$C$124),0)+IF(R27=1,(1*$C$129),0)+IF(S27=1,(1*$C$133),0)) -> 8
A28: Derecho de rectificación - Cartas físicas | B28: Amz GIL | C28: =+_xlfn.CONCAT(A28," - ",B28) -> Derecho de rectificación - Cartas físicas - Amz GIL | D28: 1 | E28: 0 | F28: 0 | G28: 0 | H28: 0 | I28: 0 | J28: 0 | K28: 0 | L28: 0 | M28: 0 | N28: 0 | O28: N/A | P28: N/A | Q28: N/A | R28: N/A | S28: N/A | T28: =+SUM(IF(D28=1,(1*$C$60),0)+IF(E28=1,(1*$C$63),0)+IF(F28=1,(1*$C$68),0)+IF(G28=1,(1*$C$75),0)+IF(H28=1,(1*$C$81),0)+IF(I28=1,(1*$C$86),0)+IF(J28=1,(1*$C$91),0)+IF(K28=1,(1*$C$96),0)+IF(L28=1,(1*$C$101),0)+IF(M28=1,(1*$C$106),0)+IF(N28=1,(1*$C$111),0)+IF(O28=1,(1*$C$115),0)+IF(P28=1,(1*$C$121),0)+IF(Q28=1,(1*$C$124),0)+IF(R28=1,(1*$C$129),0)+IF(S28=1,(1*$C$133),0)) -> 8
A29: Derecho de rectificación - Cartas físicas | B29: CB | C29: =+_xlfn.CONCAT(A29," - ",B29) -> Derecho de rectificación - Cartas físicas - CB | D29: 1 | E29: 0 | F29: 0 | G29: 0 | H29: 0 | I29: 0 | J29: 0 | K29: 0 | L29: 0 | M29: 0 | N29: 0 | O29: N/A | P29: N/A | Q29: N/A | R29: N/A | S29: N/A | T29: =+SUM(IF(D29=1,(1*$C$60),0)+IF(E29=1,(1*$C$63),0)+IF(F29=1,(1*$C$68),0)+IF(G29=1,(1*$C$75),0)+IF(H29=1,(1*$C$81),0)+IF(I29=1,(1*$C$86),0)+IF(J29=1,(1*$C$91),0)+IF(K29=1,(1*$C$96),0)+IF(L29=1,(1*$C$101),0)+IF(M29=1,(1*$C$106),0)+IF(N29=1,(1*$C$111),0)+IF(O29=1,(1*$C$115),0)+IF(P29=1,(1*$C$121),0)+IF(Q29=1,(1*$C$124),0)+IF(R29=1,(1*$C$129),0)+IF(S29=1,(1*$C$133),0)) -> 8
A30: Derecho de rectificación - Cartas físicas | B30: Branch | C30: =+_xlfn.CONCAT(A30," - ",B30) -> Derecho de rectificación - Cartas físicas - Branch | D30: 1 | E30: 0 | F30: 0 | G30: 0 | H30: 0 | I30: 0 | J30: 0 | K30: 0 | L30: 0 | M30: 0 | N30: 0 | O30: N/A | P30: N/A | Q30: N/A | R30: N/A | S30: N/A | T30: =+SUM(IF(D30=1,(1*$C$60),0)+IF(E30=1,(1*$C$63),0)+IF(F30=1,(1*$C$68),0)+IF(G30=1,(1*$C$75),0)+IF(H30=1,(1*$C$81),0)+IF(I30=1,(1*$C$86),0)+IF(J30=1,(1*$C$91),0)+IF(K30=1,(1*$C$96),0)+IF(L30=1,(1*$C$101),0)+IF(M30=1,(1*$C$106),0)+IF(N30=1,(1*$C$111),0)+IF(O30=1,(1*$C$115),0)+IF(P30=1,(1*$C$121),0)+IF(Q30=1,(1*$C$124),0)+IF(R30=1,(1*$C$129),0)+IF(S30=1,(1*$C$133),0)) -> 8
... A50: Revisión manual | B50: Branch | C50: =+_xlfn.CONCAT(A50," - ",B50) -> Revisión manual - Branch | D50: 1 | E50: 1 | F50: 0 | G50: 0 | H50: 0 | I50: 0 | J50: 0 | K50: 0 | L50: 0 | M50: 1 | N50: 1 | O50: N/A | P50: N/A | Q50: N/A | R50: N/A | S50: N/A | T50: =+SUM(IF(D50=1,(1*$C$60),0)+IF(E50=1,(1*$C$63),0)+IF(F50=1,(1*$C$68),0)+IF(G50=1,(1*$C$75),0)+IF(H50=1,(1*$C$81),0)+IF(I50=1,(1*$C$86),0)+IF(J50=1,(1*$C$91),0)+IF(K50=1,(1*$C$96),0)+IF(L50=1,(1*$C$101),0)+IF(M50=1,(1*$C$106),0)+IF(N50=1,(1*$C$111),0)+IF(O50=1,(1*$C$115),0)+IF(P50=1,(1*$C$121),0)+IF(Q50=1,(1*$C$124),0)+IF(R50=1,(1*$C$129),0)+IF(S50=1,(1*$C$133),0)) -> 94
A51: Escalados por Cumplimiento | B51: CROSS | C51: =+_xlfn.CONCAT(A51," - ",B51) -> Escalados por Cumplimiento - CROSS | D51: N/A | E51: N/A | F51: N/A | G51: N/A | H51: N/A | I51: N/A | J51: N/A | K51: N/A | L51: N/A | M51: N/A | N51: N/A | O51: 1 | P51: 0 | Q51: 0 | R51: 0 | S51: 0 | T51: =+SUM(IF(D51=1,(1*$C$60),0)+IF(E51=1,(1*$C$63),0)+IF(F51=1,(1*$C$68),0)+IF(G51=1,(1*$C$75),0)+IF(H51=1,(1*$C$81),0)+IF(I51=1,(1*$C$86),0)+IF(J51=1,(1*$C$91),0)+IF(K51=1,(1*$C$96),0)+IF(L51=1,(1*$C$101),0)+IF(M51=1,(1*$C$106),0)+IF(N51=1,(1*$C$111),0)+IF(O51=1,(1*$C$115),0)+IF(P51=1,(1*$C$121),0)+IF(Q51=1,(1*$C$124),0)+IF(R51=1,(1*$C$129),0)+IF(S51=1,(1*$C$133),0)) -> 225
A52: Creación de KPIs (necesario por Cumplimiento) | B52: CROSS | C52: =+_xlfn.CONCAT(A52," - ",B52) -> Creación de KPIs (necesario por Cumplimiento) - CROSS | D52: N/A | E52: N/A | F52: N/A | G52: N/A | H52: N/A | I52: N/A | J52: N/A | K52: N/A | L52: N/A | M52: N/A | N52: N/A | O52: 0 | P52: 1 | Q52: 0 | R52: 0 | S52: 0 | T52: =+SUM(IF(D52=1,(1*$C$60),0)+IF(E52=1,(1*$C$63),0)+IF(F52=1,(1*$C$68),0)+IF(G52=1,(1*$C$75),0)+IF(H52=1,(1*$C$81),0)+IF(I52=1,(1*$C$86),0)+IF(J52=1,(1*$C$91),0)+IF(K52=1,(1*$C$96),0)+IF(L52=1,(1*$C$101),0)+IF(M52=1,(1*$C$106),0)+IF(N52=1,(1*$C$111),0)+IF(O52=1,(1*$C$115),0)+IF(P52=1,(1*$C$121),0)+IF(Q52=1,(1*$C$124),0)+IF(R52=1,(1*$C$129),0)+IF(S52=1,(1*$C$133),0)) -> 480
A53: Gestión casos de Fraude | B53: CROSS | C53: =+_xlfn.CONCAT(A53," - ",B53) -> Gestión casos de Fraude - CROSS | D53: N/A | E53: N/A | F53: N/A | G53: N/A | H53: N/A | I53: N/A | J53: N/A | K53: N/A | L53: N/A | M53: N/A | N53: N/A | O53: 0 | P53: 0 | Q53: 1 | R53: 0 | S53: 0 | T53: =+SUM(IF(D53=1,(1*$C$60),0)+IF(E53=1,(1*$C$63),0)+IF(F53=1,(1*$C$68),0)+IF(G53=1,(1*$C$75),0)+IF(H53=1,(1*$C$81),0)+IF(I53=1,(1*$C$86),0)+IF(J53=1,(1*$C$91),0)+IF(K53=1,(1*$C$96),0)+IF(L53=1,(1*$C$101),0)+IF(M53=1,(1*$C$106),0)+IF(N53=1,(1*$C$111),0)+IF(O53=1,(1*$C$115),0)+IF(P53=1,(1*$C$121),0)+IF(Q53=1,(1*$C$124),0)+IF(R53=1,(1*$C$129),0)+IF(S53=1,(1*$C$133),0)) -> 40
A54: Control de Calidad | B54: CROSS | C54: =+_xlfn.CONCAT(A54," - ",B54) -> Control de Calidad - CROSS | D54: N/A | E54: N/A | F54: N/A | G54: N/A | H54: N/A | I54: N/A | J54: N/A | K54: N/A | L54: N/A | M54: N/A | N54: N/A | O54: 0 | P54: 0 | Q54: 0 | R54: 1 | S54: 0 | T54: =+SUM(IF(D54=1,(1*$C$60),0)+IF(E54=1,(1*$C$63),0)+IF(F54=1,(1*$C$68),0)+IF(G54=1,(1*$C$75),0)+IF(H54=1,(1*$C$81),0)+IF(I54=1,(1*$C$86),0)+IF(J54=1,(1*$C$91),0)+IF(K54=1,(1*$C$96),0)+IF(L54=1,(1*$C$101),0)+IF(M54=1,(1*$C$106),0)+IF(N54=1,(1*$C$111),0)+IF(O54=1,(1*$C$115),0)+IF(P54=1,(1*$C$121),0)+IF(Q54=1,(1*$C$124),0)+IF(R54=1,(1*$C$129),0)+IF(S54=1,(1*$C$133),0)) -> 30
A55: Buzón Schufa | B55: CROSS | C55: =+_xlfn.CONCAT(A55," - ",B55) -> Buzón Schufa - CROSS | D55: N/A | E55: N/A | F55: N/A | G55: N/A | H55: N/A | I55: N/A | J55: N/A | K55: N/A | L55: N/A | M55: N/A | N55: N/A | O55: 0 | P55: 0 | Q55: 0 | R55: 0 | S55: 1 | T55: =+SUM(IF(D55=1,(1*$C$60),0)+IF(E55=1,(1*$C$63),0)+IF(F55=1,(1*$C$68),0)+IF(G55=1,(1*$C$75),0)+IF(H55=1,(1*$C$81),0)+IF(I55=1,(1*$C$86),0)+IF(J55=1,(1*$C$91),0)+IF(K55=1,(1*$C$96),0)+IF(L55=1,(1*$C$101),0)+IF(M55=1,(1*$C$106),0)+IF(N55=1,(1*$C$111),0)+IF(O55=1,(1*$C$115),0)+IF(P55=1,(1*$C$121),0)+IF(Q55=1,(1*$C$124),0)+IF(R55=1,(1*$C$129),0)+IF(S55=1,(1*$C$133),0)) -> 45
B58: HASTA 10/02/2026
B59: Descripción del servicio | C59: MPU (min)
A60: 1 | B60: Entrada diaria de casos en buzón GDPR | C60: 8
B61: Lectura y análisis del caso | C61: 5
B62: Completar el Excel de seguimiento | C62: 3
A63: 2 | B63: Generación respuestas salientes | C63: 21
B64: Envío de la comunicación al cliente vía Picaso | C64: 5
B65: Popular Excel con los resultados (cerrar el caso) | C65: 3
B66: (Si aplica) Preparación de enlace de Tranxfer y documentación | C66: 3
B67: (Si aplica) Traducción de documentación / comunicación | C67: 10
A68: 3 | B68: Ejecución del Derecho - Acceso BNPL | C68: 33
B69: Buscar al cliente en Ops Portal | C69: 5
B70: Búsqueda de datos en Quick Sight | C70: 0
...

Sheet Catálogo de servicios v0.2
C3: RESUMEN DE MPU'S POR DERECHO GDPR (minutos) | K3: TAREAS ADICIONALES GDPR (min)
C4: Derecho de acceso | D4: Derecho de rectificación | E4: Derecho de rectificación - Cartas físicas | F4: Derecho de borrado | G4: Derecho de oposición | H4: Derecho revisión manual - incremento límite | I4: Razón de denegación | J4: Revisión manual | K4: ESCALADO | L4: KPI | M4: FRAUDE | N4: CALIDAD | O4: SCHUFA
B5: BNPL | C5: =+AB19 -> 89 | D5: =+AB23 -> 38 | E5: =+AB30 -> 25 | F5: =+AB34 -> 34 | G5: =+AB38 -> 49 | H5: =+AB42 -> 29 | I5: =+AB46 -> 29 | J5: =+AB50 -> 29 | K5: =+$AB54 -> 5 | L5: =+$AB56 -> 40 | M5: =+$AB57 -> 12 | N5: =+$AB58 -> 7 | O5: =+$AB59 -> 0
B6: Amz GIL | C6: =+AB20 -> 85 | D6: =+AB26 -> 38 | E6: =+AB31 -> 0 | F6: =+AB35 -> 34 | G6: =+AB39 -> 49 | H6: =+AB43 -> 29 | I6: =+AB47 -> 29 | J6: =+AB51 -> 29
B7: CB | C7: =+AB21 -> 92 | D7: =+AB28 -> 0 | E7: =+AB32 -> 0 | F7: =+AB36 -> 34 | G7: =+AB40 -> 29 | H7: =+AB44 -> 29 | I7: =+AB48 -> 29 | J7: =+AB52 -> 29
B8: Branch | C8: =+AB22 -> 92 | D8: =+AB29 -> 0 | E8: =+AB33 -> 0 | F8: =+AB37 -> 51 | G8: =+AB41 -> 29 | H8: =+AB45 -> 0 | I8: =+AB49 -> 29 | J8: =+AB53 -> 29
E15: =+D64 -> 8 | F15: =+D67 -> 21 | G15: =+D72 -> 60 | H15: =+D79 -> 56 | I15: =+D85 -> 63 | J15: =+D90 -> 29 | K15: =+D96 -> 17 | L15: =+D101 -> 15 | M15: =+D105 -> 20 | N15: =+D110 -> 16 | O15: =+D115 -> 15 | P15: =+D119 -> 20 | Q15: =+D124 -> 11 | R15: =+D129 -> 40 | S15: =+D134 -> 12 | T15: =+D138 -> 7 | U15: =+D142 -> 23 | V15: =+D147 -> 225 | W15: =+D153 -> 38 | X15: =+D160 -> 480 | Y15: =+D163 -> 40 | Z15: =+D168 -> 30 | AA15: =+D172 -> 35
V17: ESCALADO | W17: FRAUDA&GDPR | X17: KPI | Y17: FRAUDE | Z17: CALIDAD | AA17: SCHUFA
A18: MPU | B18: Nombre derecho | C18: Producto | D18: Servicio | E18: Tarea 1 | F18: Tarea 2 | G18: Tarea 3 | H18: Tarea 4 | I18: Tarea 5 | J18: Tarea 6 | K18: Tarea 7 | L18: Tarea 8 | M18: Tarea 9 | N18: Tarea 10 | O18: Tarea 11 | P18: Tarea 12 | Q18: Tarea 13 | R18: Tarea 14 | S18: Tarea 15 | T18: Tarea 16 | U18: Tarea 17 | V18: Tarea 18 | W18: Tarea 19 | X18: Tarea 20 | Y18: Tarea 21 | Z18: Tarea 22 | AA18: Tarea 23 | AB18: MPU | AC18: Nueva fórmula
B19: Derecho de acceso | C19: BNPL | D19: =+_xlfn.CONCAT(B19," - ",C19) -> Derecho de acceso - BNPL | E19: 1 | F19: 1 | G19: 1 | H19: 0 | I19: 0 | J19: 0 | K19: 0 | L19: 0 | M19: 0 | N19: 0 | O19: 0 | P19: 0 | Q19: 0 | R19: 0 | S19: 0 | T19: 0 | U19: 0 | V19: N/A | W19: N/A | X19: N/A | Y19: N/A | Z19: N/A | AA19: N/A | AB19: =+SUM(IF(E19=1,(1*$D$64),0)+IF(F19=1,(1*$D$67),0)+IF(G19=1,(1*$D$72),0)+IF(H19=1,(1*$D$79),0)+IF(I19=1,(1*$D$85),0)+IF(J19=1,(1*$D$91),0)+IF(K19=1,(1*$D$96),0)+IF(L19=1,(1*$D$101),0)+IF(M19=1,(1*$D$106),0)+IF(N19=1,(1*$D$111),0)+IF(O19=1,(1*$D$116),0)+IF(P19=1,(1*$D$119),0)+IF(V19=1,(1*$D$120),0)+IF(W19=1,(1*$D$126),0)+IF(X19=1,(1*$D$129),0)+IF(Y19=1,(1*$D$134),0)+IF(Z19=1,(1*$D$138),0)) -> 89 | AC19: =SUMIF($E19:$AA19,1,$E$15:$AA$15) -> 89
B20: Derecho de acceso | C20: Amz GIL | D20: =+_xlfn.CONCAT(B20," - ",C20) -> Derecho de acceso - Amz GIL | E20: 1 | F20: 1 | G20: 0 | H20: 1 | I20: 0 | J20: 0 | K20: 0 | L20: 0 | M20: 0 | N20: 0 | O20: 0 | P20: 0 | Q20: 0 | R20: 0 | S20: 0 | T20: 0 | U20: 0 | V20: N/A | W20: N/A | X20: N/A | Y20: N/A | Z20: N/A | AA20: N/A | AB20: =+SUM(IF(E20=1,(1*$D$64),0)+IF(F20=1,(1*$D$67),0)+IF(G20=1,(1*$D$72),0)+IF(H20=1,(1*$D$79),0)+IF(I20=1,(1*$D$85),0)+IF(J20=1,(1*$D$91),0)+IF(K20=1,(1*$D$96),0)+IF(L20=1,(1*$D$101),0)+IF(M20=1,(1*$D$106),0)+IF(N20=1,(1*$D$111),0)+IF(O20=1,(1*$D$116),0)+IF(P20=1,(1*$D$119),0)+IF(V20=1,(1*$D$120),0)+IF(W20=1,(1*$D$126),0)+IF(X20=1,(1*$D$129),0)+IF(Y20=1,(1*$D$134),0)+IF(Z20=1,(1*$D$138),0)) -> 85 | AC20: =SUMIF($E20:$AA20,1,$E$15:$AA$15) -> 85
B21: Derecho de acceso | C21: CB | D21: =+_xlfn.CONCAT(B21," - ",C21) -> Derecho de acceso - CB | E21: 1 | F21: 1 | G21: 0 | H21: 0 | I21: 1 | J21: 0 | K21: 0 | L21: 0 | M21: 0 | N21: 0 | O21: 0 | P21: 0 | Q21: 0 | R21: 0 | S21: 0 | T21: 0 | U21: 0 | V21: N/A | W21: N/A | X21: N/A | Y21: N/A | Z21: N/A | AA21: N/A | AB21: =+SUM(IF(E21=1,(1*$D$64),0)+IF(F21=1,(1*$D$67),0)+IF(G21=1,(1*$D$72),0)+IF(H21=1,(1*$D$79),0)+IF(I21=1,(1*$D$85),0)+IF(J21=1,(1*$D$91),0)+IF(K21=1,(1*$D$96),0)+IF(L21=1,(1*$D$101),0)+IF(M21=1,(1*$D$106),0)+IF(N21=1,(1*$D$111),0)+IF(O21=1,(1*$D$116),0)+IF(P21=1,(1*$D$119),0)+IF(V21=1,(1*$D$120),0)+IF(W21=1,(1*$D$126),0)+IF(X21=1,(1*$D$129),0)+IF(Y21=1,(1*$D$134),0)+IF(Z21=1,(1*$D$138),0)) -> 92 | AC21: =SUMIF($E21:$AA21,1,$E$15:$AA$15) -> 92
B22: Derecho de acceso | C22: Branch | D22: =+_xlfn.CONCAT(B22," - ",C22) -> Derecho de acceso - Branch | E22: 1 | F22: 1 | G22: 0 | H22: 0 | I22: 1 | J22: 0 | K22: 0 | L22: 0 | M22: 0 | N22: 0 | O22: 0 | P22: 0 | Q22: 0 | R22: 0 | S22: 0 | T22: 0 | U22: 0 | V22: N/A | W22: N/A | X22: N/A | Y22: N/A | Z22: N/A | AA22: N/A | AB22: =+SUM(IF(E22=1,(1*$D$64),0)+IF(F22=1,(1*$D$67),0)+IF(G22=1,(1*$D$72),0)+IF(H22=1,(1*$D$79),0)+IF(I22=1,(1*$D$85),0)+IF(J22=1,(1*$D$91),0)+IF(K22=1,(1*$D$96),0)+IF(L22=1,(1*$D$101),0)+IF(M22=1,(1*$D$106),0)+IF(N22=1,(1*$D$111),0)+IF(O22=1,(1*$D$116),0)+IF(P22=1,(1*$D$119),0)+IF(V22=1,(1*$D$120),0)+IF(W22=1,(1*$D$126),0)+IF(X22=1,(1*$D$129),0)+IF(Y22=1,(1*$D$134),0)+IF(Z22=1,(1*$D$138),0)) -> 92 | AC22: =SUMIF($E22:$AA22,1,$E$15:$AA$15) -> 92
B23: Derecho de rectificación | C23: BNPL (Email/Teléfono) | D23: =+_xlfn.CONCAT(B23," - ",C23) -> Derecho de rectificación - BNPL (Email/Teléfono) | E23: 1 | F23: 1 | G23: 0 | H23: 0 | I23: 0 | J23: 1 | K23: 0 | L23: 0 | M23: 0 | N23: 0 | O23: 0 | P23: 0 | Q23: 0 | R23: 0 | S23: 0 | T23: 0 | U23: 0 | V23: N/A | W23: N/A | X23: N/A | Y23: N/A | Z23: N/A | AA23: N/A | AB23: =+SUM(IF(E23=1,(1*$D$64),0)+IF(F23=1,(1*$D$67),0)+IF(G23=1,(1*$D$72),0)+IF(H23=1,(1*$D$79),0)+IF(I23=1,(1*$D$85),0)+IF(J23=1,(1*$D$91),0)+IF(K23=1,(1*$D$96),0)+IF(L23=1,(1*$D$101),0)+IF(M23=1,(1*$D$106),0)+IF(N23=1,(1*$D$111),0)+IF(O23=1,(1*$D$116),0)+IF(P23=1,(1*$D$119),0)+IF(V23=1,(1*$D$120),0)+IF(W23=1,(1*$D$126),0)+IF(X23=1,(1*$D$129),0)+IF(Y23=1,(1*$D$134),0)+IF(Z23=1,(1*$D$138),0)) -> 38 | AC23: =SUMIF($E23:$AA23,1,$E$15:$AA$15) -> 58
B24: Derecho de rectificación | C24: BNPL (IBAN) | D24: =+_xlfn.CONCAT(B24," - ",C24) -> Derecho de rectificación - BNPL (IBAN) | E24: 1 | F24: 1 | G24: 0 | H24: 0 | I24: 0 | J24: 0 | K24: 0 | L24: 1 | M24: 0 | N24: 0 | O24: 0 | P24: 0 | Q24: 0 | R24: 0 | S24: 0 | T24: 0 | U24: 0 | V24: N/A | W24: N/A | X24: N/A | Y24: N/A | Z24: N/A | AA24: N/A | AB24: =+SUM(IF(E24=1,(1*$D$64),0)+IF(F24=1,(1*$D$67),0)+IF(G24=1,(1*$D$72),0)+IF(H24=1,(1*$D$79),0)+IF(I24=1,(1*$D$85),0)+IF(J24=1,(1*$D$91),0)+IF(K24=1,(1*$D$96),0)+IF(L24=1,(1*$D$101),0)+IF(M24=1,(1*$D$106),0)+IF(N24=1,(1*$D$111),0)+IF(O24=1,(1*$D$116),0)+IF(P24=1,(1*$D$119),0)+IF(V24=1,(1*$D$120),0)+IF(W24=1,(1*$D$126),0)+IF(X24=1,(1*$D$129),0)+IF(Y24=1,(1*$D$134),0)+IF(Z24=1,(1*$D$138),0)) -> 44 | AC24: =SUMIF($E24:$AA24,1,$E$15:$AA$15) -> 44
B25: Derecho de rectificación | C25: BNPL (Dirección, Nombre, Fecha de Nacimiento) | D25: =+_xlfn.CONCAT(B25," - ",C25) -> Derecho de rectificación - BNPL (Dirección, Nombre, Fecha de Nacimiento) | E25: 1 | F25: 1 | G25: 0 | H25: 0 | I25: 0 | J25: 1 | K25: 0 | L25: 0 | M25: 0 | N25: 0 | O25: 0 | P25: 0 | Q25: 0 | R25: 0 | S25: 0 | T25: 0 | U25: 0 | V25: N/A | W25: N/A | X25: N/A | Y25: N/A | Z25: N/A | AA25: N/A | AB25: =+SUM(IF(E25=1,(1*$D$64),0)+IF(F25=1,(1*$D$67),0)+IF(G25=1,(1*$D$72),0)+IF(H25=1,(1*$D$79),0)+IF(I25=1,(1*$D$85),0)+IF(J25=1,(1*$D$91),0)+IF(K25=1,(1*$D$96),0)+IF(L25=1,(1*$D$101),0)+IF(M25=1,(1*$D$106),0)+IF(N25=1,(1*$D$111),0)+IF(O25=1,(1*$D$116),0)+IF(P25=1,(1*$D$119),0)+IF(V25=1,(1*$D$120),0)+IF(W25=1,(1*$D$126),0)+IF(X25=1,(1*$D$129),0)+IF(Y25=1,(1*$D$134),0)+IF(Z25=1,(1*$D$138),0)) -> 38 | AC25: =SUMIF($E25:$AA25,1,$E$15:$AA$15) -> 58
B26: Derecho de rectificación | C26: Amz GIL (Email / Teléfono) | D26: =+_xlfn.CONCAT(B26," - ",C26) -> Derecho de rectificación - Amz GIL (Email / Teléfono) | E26: 1 | F26: 1 | G26: 0 | H26: 0 | I26: 0 | J26: 1 | K26: 0 | L26: 0 | M26: 0 | N26: 0 | O26: 0 | P26: 0 | Q26: 0 | R26: 0 | S26: 0 | T26: 0 | U26: 0 | V26: N/A | W26: N/A | X26: N/A | Y26: N/A | Z26: N/A | AA26: N/A | AB26: =+SUM(IF(E26=1,(1*$D$64),0)+IF(F26=1,(1*$D$67),0)+IF(G26=1,(1*$D$72),0)+IF(H26=1,(1*$D$79),0)+IF(I26=1,(1*$D$85),0)+IF(J26=1,(1*$D$91),0)+IF(K26=1,(1*$D$96),0)+IF(L26=1,(1*$D$101),0)+IF(M26=1,(1*$D$106),0)+IF(N26=1,(1*$D$111),0)+IF(O26=1,(1*$D$116),0)+IF(P26=1,(1*$D$119),0)+IF(V26=1,(1*$D$120),0)+IF(W26=1,(1*$D$126),0)+IF(X26=1,(1*$D$129),0)+IF(Y26=1,(1*$D$134),0)+IF(Z26=1,(1*$D$138),0)) -> 38 | AC26: =SUMIF($E26:$AA26,1,$E$15:$AA$15) -> 58
B27: Derecho de rectificación | C27: Amz GIL (Dirección, Nombre, Fecha de Nacimiento) | D27: =+_xlfn.CONCAT(B27," - ",C27) -> Derecho de rectificación - Amz GIL (Dirección, Nombre, Fecha de Nacimiento) | E27: 1 | F27: 1 | G27: 0 | H27: 0 | I27: 0 | J27: 0 | K27: 0 | L27: 0 | M27: 1 | N27: 0 | O27: 0 | P27: 0 | Q27: 0 | R27: 0 | S27: 0 | T27: 0 | U27: 0 | V27: N/A | W27: N/A | X27: N/A | Y27: N/A | Z27: N/A | AA27: N/A | AB27: =+SUM(IF(E27=1,(1*$D$64),0)+IF(F27=1,(1*$D$67),0)+IF(G27=1,(1*$D$72),0)+IF(H27=1,(1*$D$79),0)+IF(I27=1,(1*$D$85),0)+IF(J27=1,(1*$D$91),0)+IF(K27=1,(1*$D$96),0)+IF(L27=1,(1*$D$101),0)+IF(M27=1,(1*$D$106),0)+IF(N27=1,(1*$D$111),0)+IF(O27=1,(1*$D$116),0)+IF(P27=1,(1*$D$119),0)+IF(V27=1,(1*$D$120),0)+IF(W27=1,(1*$D$126),0)+IF(X27=1,(1*$D$129),0)+IF(Y27=1,(1*$D$134),0)+IF(Z27=1,(1*$D$138),0)) -> 34 | AC27: =SUMIF($E27:$AA27,1,$E$15:$AA$15) -> 49
B28: Derecho de rectificación | C28: CB | D28: =+_xlfn.CONCAT(B28," - ",C28) -> Derecho de rectificación - CB | E28: 0 | F28: 0 | G28: 0 | H28: 0 | I28: 0 | J28: 0 | K28: 0 | L28: 0 | M28: 0 | N28: 0 | O28: 0 | P28: 0 | Q28: 0 | R28: 0 | S28: 0 | T28: 0 | U28: 0 | V28: N/A | W28: N/A | X28: N/A | Y28: N/A | Z28: N/A | AA28: N/A | AB28: =+SUM(IF(E28=1,(1*$D$64),0)+IF(F28=1,(1*$D$67),0)+IF(G28=1,(1*$D$72),0)+IF(H28=1,(1*$D$79),0)+IF(I28=1,(1*$D$85),0)+IF(J28=1,(1*$D$91),0)+IF(K28=1,(1*$D$96),0)+IF(L28=1,(1*$D$101),0)+IF(M28=1,(1*$D$106),0)+IF(N28=1,(1*$D$111),0)+IF(O28=1,(1*$D$116),0)+IF(P28=1,(1*$D$119),0)+IF(V28=1,(1*$D$120),0)+IF(W28=1,(1*$D$126),0)+IF(X28=1,(1*$D$129),0)+IF(Y28=1,(1*$D$134),0)+IF(Z28=1,(1*$D$138),0)) -> 0 | AC28: =SUMIF($E28:$AA28,1,$E$15:$AA$15) -> 0
B29: Derecho de rectificación | C29: Branch | D29: =+_xlfn.CONCAT(B29," - ",C29) -> Derecho de rectificación - Branch | E29: 0 | F29: 0 | G29: 0 | H29: 0 | I29: 0 | J29: 0 | K29: 0 | L29: 0 | M29: 0 | N29: 0 | O29: 0 | P29: 0 | Q29: 0 | R29: 0 | S29: 0 | T29: 0 | U29: 0 | V29: N/A | W29: N/A | X29: N/A | Y29: N/A | Z29: N/A | AA29: N/A | AB29: =+SUM(IF(E29=1,(1*$D$64),0)+IF(F29=1,(1*$D$67),0)+IF(G29=1,(1*$D$72),0)+IF(H29=1,(1*$D$79),0)+IF(I29=1,(1*$D$85),0)+IF(J29=1,(1*$D$91),0)+IF(K29=1,(1*$D$96),0)+IF(L29=1,(1*$D$101),0)+IF(M29=1,(1*$D$106),0)+IF(N29=1,(1*$D$111),0)+IF(O29=1,(1*$D$116),0)+IF(P29=1,(1*$D$119),0)+IF(V29=1,(1*$D$120),0)+IF(W29=1,(1*$D$126),0)+IF(X29=1,(1*$D$129),0)+IF(Y29=1,(1*$D$134),0)+IF(Z29=1,(1*$D$138),0)) -> 0 | AC29: =SUMIF($E29:$AA29,1,$E$15:$AA$15) -> 0
B30: Derecho de rectificación - Cartas físicas | C30: BNPL | D30: =+_xlfn.CONCAT(B30," - ",C30) -> Derecho de rectificación - Cartas físicas - BNPL | E30: 1 | F30: 0 | G30: 0 | H30: 0 | I30: 0 | J30: 0 | K30: 1 | L30: 0 | M30: 0 | N30: 0 | O30: 0 | P30: 0 | Q30: 0 | R30: 0 | S30: 0 | T30: 0 | U30: 0 | V30: N/A | W30: N/A | X30: N/A | Y30: N/A | Z30: N/A | AA30: N/A | AB30: =+SUM(IF(E30=1,(1*$D$64),0)+IF(F30=1,(1*$D$67),0)+IF(G30=1,(1*$D$72),0)+IF(H30=1,(1*$D$79),0)+IF(I30=1,(1*$D$85),0)+IF(J30=1,(1*$D$91),0)+IF(K30=1,(1*$D$96),0)+IF(L30=1,(1*$D$101),0)+IF(M30=1,(1*$D$106),0)+IF(N30=1,(1*$D$111),0)+IF(O30=1,(1*$D$116),0)+IF(P30=1,(1*$D$119),0)+IF(V30=1,(1*$D$120),0)+IF(W30=1,(1*$D$126),0)+IF(X30=1,(1*$D$129),0)+IF(Y30=1,(1*$D$134),0)+IF(Z30=1,(1*$D$138),0)) -> 25 | AC30: =SUMIF($E30:$AA30,1,$E$15:$AA$15) -> 25
... B53: Revisión manual | C53: Branch | D53: =+_xlfn.CONCAT(B53," - ",C53) -> Revisión manual - Branch | E53: 1 | F53: 1 | G53: 0 | H53: 0 | I53: 0 | J53: 0 | K53: 0 | L53: 0 | M53: 0 | N53: 0 | O53: 0 | P53: 0 | Q53: 0 | R53: 1 | S53: 0 | T53: 0 | U53: 0 | V53: N/A | W53: N/A | X53: N/A | Y53: N/A | Z53: N/A | AA53: N/A | AB53: =+SUM(IF(E53=1,(1*$D$64),0)+IF(F53=1,(1*$D$67),0)+IF(G53=1,(1*$D$72),0)+IF(H53=1,(1*$D$79),0)+IF(I53=1,(1*$D$85),0)+IF(J53=1,(1*$D$91),0)+IF(K53=1,(1*$D$96),0)+IF(L53=1,(1*$D$101),0)+IF(M53=1,(1*$D$106),0)+IF(N53=1,(1*$D$111),0)+IF(O53=1,(1*$D$116),0)+IF(P53=1,(1*$D$119),0)+IF(V53=1,(1*$D$120),0)+IF(W53=1,(1*$D$126),0)+IF(X53=1,(1*$D$129),0)+IF(Y53=1,(1*$D$134),0)+IF(Z53=1,(1*$D$138),0)) -> 29 | AC53: =SUMIF($E53:$AA53,1,$E$15:$AA$15) -> 69
B54: Escalados por Cumplimiento | C54: CROSS | D54: =+_xlfn.CONCAT(B54," - ",C54) -> Escalados por Cumplimiento - CROSS | E54: N/A | F54: N/A | G54: N/A | H54: N/A | I54: N/A | J54: N/A | K54: N/A | L54: N/A | M54: N/A | N54: N/A | O54: N/A | P54: N/A | Q54: N/A | R54: N/A | S54: N/A | T54: N/A | U54: N/A | V54: 1 | W54: 0 | X54: 0 | Y54: 0 | Z54: 0 | AA54: 0 | AB54: =+SUM(IF(E54=1,(1*$D$64),0)+IF(F54=1,(1*$D$67),0)+IF(G54=1,(1*$D$72),0)+IF(H54=1,(1*$D$79),0)+IF(I54=1,(1*$D$85),0)+IF(J54=1,(1*$D$91),0)+IF(K54=1,(1*$D$96),0)+IF(L54=1,(1*$D$101),0)+IF(M54=1,(1*$D$106),0)+IF(N54=1,(1*$D$111),0)+IF(O54=1,(1*$D$116),0)+IF(P54=1,(1*$D$119),0)+IF(V54=1,(1*$D$120),0)+IF(W54=1,(1*$D$126),0)+IF(X54=1,(1*$D$129),0)+IF(Y54=1,(1*$D$134),0)+IF(Z54=1,(1*$D$138),0)) -> 5 | AC54: =SUMIF($E54:$AA54,1,$E$15:$AA$15) -> 225
B55: =+C153 -> Suplantación Identidad (combinado con GDPR) | C55: CROSS | D55: =+_xlfn.CONCAT(B55," - ",C55) -> Suplantación Identidad (combinado con GDPR) - CROSS | E55: N/A | F55: N/A | G55: N/A | H55: N/A | I55: N/A | J55: N/A | K55: N/A | L55: N/A | M55: N/A | N55: N/A | O55: N/A | P55: N/A | Q55: N/A | R55: N/A | S55: N/A | T55: N/A | U55: N/A | V55: 0 | W55: 1 | X55: 0 | Y55: 0 | Z55: 0 | AA55: 0 | AB55: =+SUM(IF(E55=1,(1*$D$64),0)+IF(F55=1,(1*$D$67),0)+IF(G55=1,(1*$D$72),0)+IF(H55=1,(1*$D$79),0)+IF(I55=1,(1*$D$85),0)+IF(J55=1,(1*$D$91),0)+IF(K55=1,(1*$D$96),0)+IF(L55=1,(1*$D$101),0)+IF(M55=1,(1*$D$106),0)+IF(N55=1,(1*$D$111),0)+IF(O55=1,(1*$D$116),0)+IF(P55=1,(1*$D$119),0)+IF(V55=1,(1*$D$120),0)+IF(W55=1,(1*$D$126),0)+IF(X55=1,(1*$D$129),0)+IF(Y55=1,(1*$D$134),0)+IF(Z55=1,(1*$D$138),0)) -> 6 | AC55: =SUMIF($E55:$AA55,1,$E$15:$AA$15) -> 38
